Workbook
Name Equip_Belt_Grades: '장비 등급별 옵션'!$A$30:$A$34
Name Equip_Bracelet_Grades: '장비 등급별 옵션'!$J$16:$J$20
Name Equip_Earring_Grades: '장비 등급별 옵션'!$J$37:$J$40
Name Equip_Jacket_Grades: '장비 등급별 옵션'!$A$2:$A$6
Name Equip_MagicStone_Grades: '장비 등급별 옵션'!$J$30:$J$33
Name Equip_Necklace_Grades: '장비 등급별 옵션'!$J$2:$J$6
Name Equip_Pants_Grades: '장비 등급별 옵션'!$A$16:$A$20
Name Equip_Ring_Grades: '장비 등급별 옵션'!$J$9:$J$13
Name Equip_Shoes_Grades: '장비 등급별 옵션'!$A$23:$A$27
Name Equip_Shoulder_Grades: '장비 등급별 옵션'!$A$9:$A$13
Name Equip_SubEquipment_Grades: '장비 등급별 옵션'!$J$23:$J$26

Sheet 장비 세트 단계
A1: 세트단계 | B1: 필요 세트포인트 | C1: 변경 후 장비점수 | D1: 변경 후 스탯(필수) | E1: 상의 | F1: 머리어깨 | G1: 하의 | H1: 신발 | I1: 허리 | J1: 목걸이 | K1: 반지 | L1: 팔찌 | M1: 보조장비 | N1: 마법석 | O1: 귀걸이 | P1: 공격력증가 | Q1: 이전 단계 전후비(%) | R1: 세트 단계 최종뎀(%) | S1: 장비최종뎀곱 | T1: 장비공격력증가합 | U1: 장비속강합 | V1: 장비쿨감합(참고) | W1: 장비힘합 | X1: 장비본체옵션전후비 | Y1: 공격력증가전후비 | Z1: 주스탯전후비 | AA1: 세트제외보정점수 | AB1: 전체점수전후비 | AC1: 세트단계전후비 | AD1: 최종뎀 0.1% 반올림 | AE1: 검산 장비점수 | AF1: 검산 오차
A2: 레어 I | B2: 750 | C2: 719 | D2: =$D$25+W2-$W$25 -> 6306 | E2: 유니크 | F2: 레어 | G2: 레어 | H2: 레어 | I2: 레어 | J2: 레어 | K2: 레어 | L2: 레어 | M2: 레어 | N2: 레어 | O2: 레어 | P2: 0 | Q2: =0 -> 0 | R2: =IF(OR(AC2="",$AC$2="",$R$25=""),"",(AC2/$AC$2*(1+$R$25/100)-1)*100) -> 4 | S2: =(1+IFERROR(VLOOKUP(E2,'장비 등급별 옵션'!$A$2:$D$6,3,FALSE),0)/100)*(1+IFERROR(VLOOKUP(F2,'장비 등급별 옵션'!$A$9:$D$13,3,FALSE),0)/100)*(1+IFERROR(VLOOKUP(G2,'장비 등급별 옵션'!$A$16:$D$20,3,FALSE),0)/100)*(1+IFERROR(VLOOKUP(H2,'장비 등급별 옵션'!$A$23:$D$27,3,FALSE),0)/100)*(1+IFERROR(VLOOKUP(I2,'장비 등급별 옵션'!$A$30:$D$34,3,FALSE),0)/100)*(1+IFERROR(VLOOKUP(J2,'장비 등급별 옵션'!$J$2:$N$6,3,FALSE),0)/100)*(1+IFERROR(VLOOKUP(K2,'장비 등급별 옵션'!$J$9:$N$13,3,FALSE),0)/100)*(1+IFERROR(VLOOKUP(L2,'장비 등급별 옵션'!$J$16:$N$20,3,FALSE),0)/100)*(1+IFERROR(VLOOKUP(M2,'장비 등급별 옵션'!$J$23:$N$27,3,FALSE),0)/100)*(1+IFERROR(VLOOKUP(N2,'장비 등급별 옵션'!$J$30:$N$34,3,FALSE),0)/100)*(1+IFERROR(VLOOKUP(O2,'장비 등급별 옵션'!$J$37:$N$40,3,FALSE),0)/100) -> 68.080797 | T2: =IFERROR(VLOOKUP(E2,'장비 등급별 옵션'!$A$2:$D$6,2,FALSE),0)+IFERROR(VLOOKUP(F2,'장비 등급별 옵션'!$A$9:$D$13,2,FALSE),0)+IFERROR(VLOOKUP(G2,'장비 등급별 옵션'!$A$16:$D$20,2,FALSE),0)+IFERROR(VLOOKUP(H2,'장비 등급별 옵션'!$A$23:$D$27,2,FALSE),0)+IFERROR(VLOOKUP(I2,'장비 등급별 옵션'!$A$30:$D$34,2,FALSE),0)+IFERROR(VLOOKUP(J2,'장비 등급별 옵션'!$J$2:$N$6,2,FALSE),0)+IFERROR(VLOOKUP(K2,'장비 등급별 옵션'!$J$9:$N$13,2,FALSE),0)+IFERROR(VLOOKUP(L2,'장비 등급별 옵션'!$J$16:$N$20,2,FALSE),0)+IFERROR(VLOOKUP(M2,'장비 등급별 옵션'!$J$23:$N$27,2,FALSE),0)+IFERROR(VLOOKUP(N2,'장비 등급별 옵션'!$J$30:$N$34,2,FALSE),0)+IFERROR(VLOOKUP(O2,'장비 등급별 옵션'!$J$37:$N$40,2,FALSE),0) -> 24189 | U2: =IFERROR(VLOOKUP(E2,'장비 등급별 옵션'!$A$2:$D$6,4,FALSE),0)+IFERROR(VLOOKUP(F2,'장비 등급별 옵션'!$A$9:$D$13,4,FALSE),0)+IFERROR(VLOOKUP(G2,'장비 등급별 옵션'!$A$16:$D$20,4,FALSE),0)+IFERROR(VLOOKUP(H2,'장비 등급별 옵션'!$A$23:$D$27,4,FALSE),0)+IFERROR(VLOOKUP(I2,'장비 등급별 옵션'!$A$30:$D$34,4,FALSE),0)+IFERROR(VLOOKUP(J2,'장비 등급별 옵션'!$J$2:$N$6,4,FALSE),0)+IFERROR(VLOOKUP(K2,'장비 등급별 옵션'!$J$9:$N$13,4,FALSE),0)+IFERROR(VLOOKUP(L2,'장비 등급별 옵션'!$J$16:$N$20,4,FALSE),0)+IFERROR(VLOOKUP(M2,'장비 등급별 옵션'!$J$23:$N$27,4,FALSE),0)+IFERROR(VLOOKUP(N2,'장비 등급별 옵션'!$J$30:$N$34,4,FALSE),0)+IFERROR(VLOOKUP(O2,'장비 등급별 옵션'!$J$37:$N$40,4,FALSE),0) -> 130 | V2: =IFERROR(VLOOKUP(E2,'장비 등급별 옵션'!$A$2:$D$6,5,FALSE),0)+IFERROR(VLOOKUP(F2,'장비 등급별 옵션'!$A$9:$D$13,5,FALSE),0)+IFERROR(VLOOKUP(G2,'장비 등급별 옵션'!$A$16:$D$20,5,FALSE),0)+IFERROR(VLOOKUP(H2,'장비 등급별 옵션'!$A$23:$D$27,5,FALSE),0)+IFERROR(VLOOKUP(I2,'장비 등급별 옵션'!$A$30:$D$34,5,FALSE),0)+IFERROR(VLOOKUP(J2,'장비 등급별 옵션'!$J$2:$N$6,5,FALSE),0)+IFERROR(VLOOKUP(K2,'장비 등급별 옵션'!$J$9:$N$13,5,FALSE),0)+IFERROR(VLOOKUP(L2,'장비 등급별 옵션'!$J$16:$N$20,5,FALSE),0)+IFERROR(VLOOKUP(M2,'장비 등급별 옵션'!$J$23:$N$27,5,FALSE),0)+IFERROR(VLOOKUP(N2,'장비 등급별 옵션'!$J$30:$N$34,5,FALSE),0)+IFERROR(VLOOKUP(O2,'장비 등급별 옵션'!$J$37:$N$40,5,FALSE),0) -> 15 | W2: =IFERROR(VLOOKUP(E2,'장비 등급별 옵션'!$A$2:$H$6,5,FALSE),0)+IFERROR(VLOOKUP(F2,'장비 등급별 옵션'!$A$9:$H$13,5,FALSE),0)+IFERROR(VLOOKUP(G2,'장비 등급별 옵션'!$A$16:$H$20,5,FALSE),0)+IFERROR(VLOOKUP(H2,'장비 등급별 옵션'!$A$23:$H$27,5,FALSE),0)+IFERROR(VLOOKUP(I2,'장비 등급별 옵션'!$A$30:$H$34,5,FALSE),0)+IFERROR(VLOOKUP(J2,'장비 등급별 옵션'!$J$2:$R$6,6,FALSE),0)+IFERROR(VLOOKUP(K2,'장비 등급별 옵션'!$J$9:$R$13,6,FALSE),0)+IFERROR(VLOOKUP(L2,'장비 등급별 옵션'!$J$16:$R$20,6,FALSE),0)+IFERROR(VLOOKUP(M2,'장비 등급별 옵션'!$J$23:$R$27,6,FALSE),0)+IFERROR(VLOOKUP(N2,'장비 등급별 옵션'!$J$30:$R$34,6,FALSE),0)+IFERROR(VLOOKUP(O2,'장비 등급별 옵션'!$J$37:$R$40,6,FALSE),0) -> 1572 | X2: =(S2*((1.05+U2*0.0045)/1.05))/($S$25*((1.05+$U$25*0.0045)/1.05)) -> 0.50984421 | Y2: =IF($C$27="","",(1+($C$27+T2-$T$25+P2-$P$25)/100)/(1+$C$27/100)) -> 0.68264423 | Z2: =IF(OR(D2="",$D$25="",$Q$25=""),"",(1+(D2+168350+297900+TRUNC(3.08*(D2-$Q$25)+2886))/250)/(1+($D$25+168350+297900+TRUNC(3.08*($D$25-$Q$25)+2886))/250)) -> 0.99878576 | AA2: =IF(OR(C2="",X2="",Y2="",Z2=""),"",C2/X2/Y2/Z2) -> 2068.3529 | AB2: =IF(OR(C2="",$C$25=""),"",C2/$C$25) -> 0.052646994 | AC2: =IF(OR(AB2="",X2="",Y2="",Z2=""),"",AB2/X2/Y2/Z2) -> 0.15145001 | AD2: =IF(R2="","",ROUND(R2,1)) -> 4 | AE2: =IF(OR($C$25="",X2="",Y2="",Z2="",AC2=""),"",ROUND($C$25*X2*Y2*Z2*AC2,0)) -> 719 | AF2: =IF(OR(AE2="",C2=""),"",AE2-C2) -> 0
A3: 레어 II | B3: 830 | C3: 747 | D3: =$D$25+W3-$W$25 -> 6306 | E3: 유니크 | F3: 레어 | G3: 레어 | H3: 레어 | I3: 레어 | J3: 레어 | K3: 레어 | L3: 레어 | M3: 레어 | N3: 레어 | O3: 레어 | P3: 0 | Q3: =IF(OR(R3="",R2=""),"",((1+R3/100)/(1+R2/100)-1)*100) -> 3.8942976 | R3: =IF(OR(AC3="",$AC$2="",$R$25=""),"",(AC3/$AC$2*(1+$R$25/100)-1)*100) -> 8.0500695 | S3: =(1+IFERROR(VLOOKUP(E3,'장비 등급별 옵션'!$A$2:$D$6,3,FALSE),0)/100)*(1+IFERROR(VLOOKUP(F3,'장비 등급별 옵션'!$A$9:$D$13,3,FALSE),0)/100)*(1+IFERROR(VLOOKUP(G3,'장비 등급별 옵션'!$A$16:$D$20,3,FALSE),0)/100)*(1+IFERROR(VLOOKUP(H3,'장비 등급별 옵션'!$A$23:$D$27,3,FALSE),0)/100)*(1+IFERROR(VLOOKUP(I3,'장비 등급별 옵션'!$A$30:$D$34,3,FALSE),0)/100)*(1+IFERROR(VLOOKUP(J3,'장비 등급별 옵션'!$J$2:$N$6,3,FALSE),0)/100)*(1+IFERROR(VLOOKUP(K3,'장비 등급별 옵션'!$J$9:$N$13,3,FALSE),0)/100)*(1+IFERROR(VLOOKUP(L3,'장비 등급별 옵션'!$J$16:$N$20,3,FALSE),0)/100)*(1+IFERROR(VLOOKUP(M3,'장비 등급별 옵션'!$J$23:$N$27,3,FALSE),0)/100)*(1+IFERROR(VLOOKUP(N3,'장비 등급별 옵션'!$J$30:$N$34,3,FALSE),0)/100)*(1+IFERROR(VLOOKUP(O3,'장비 등급별 옵션'!$J$37:$N$40,3,FALSE),0)/100) -> 68.080797 | T3: =IFERROR(VLOOKUP(E3,'장비 등급별 옵션'!$A$2:$D$6,2,FALSE),0)+IFERROR(VLOOKUP(F3,'장비 등급별 옵션'!$A$9:$D$13,2,FALSE),0)+IFERROR(VLOOKUP(G3,'장비 등급별 옵션'!$A$16:$D$20,2,FALSE),0)+IFERROR(VLOOKUP(H3,'장비 등급별 옵션'!$A$23:$D$27,2,FALSE),0)+IFERROR(VLOOKUP(I3,'장비 등급별 옵션'!$A$30:$D$34,2,FALSE),0)+IFERROR(VLOOKUP(J3,'장비 등급별 옵션'!$J$2:$N$6,2,FALSE),0)+IFERROR(VLOOKUP(K3,'장비 등급별 옵션'!$J$9:$N$13,2,FALSE),0)+IFERROR(VLOOKUP(L3,'장비 등급별 옵션'!$J$16:$N$20,2,FALSE),0)+IFERROR(VLOOKUP(M3,'장비 등급별 옵션'!$J$23:$N$27,2,FALSE),0)+IFERROR(VLOOKUP(N3,'장비 등급별 옵션'!$J$30:$N$34,2,FALSE),0)+IFERROR(VLOOKUP(O3,'장비 등급별 옵션'!$J$37:$N$40,2,FALSE),0) -> 24189 | U3: =IFERROR(VLOOKUP(E3,'장비 등급별 옵션'!$A$2:$D$6,4,FALSE),0)+IFERROR(VLOOKUP(F3,'장비 등급별 옵션'!$A$9:$D$13,4,FALSE),0)+IFERROR(VLOOKUP(G3,'장비 등급별 옵션'!$A$16:$D$20,4,FALSE),0)+IFERROR(VLOOKUP(H3,'장비 등급별 옵션'!$A$23:$D$27,4,FALSE),0)+IFERROR(VLOOKUP(I3,'장비 등급별 옵션'!$A$30:$D$34,4,FALSE),0)+IFERROR(VLOOKUP(J3,'장비 등급별 옵션'!$J$2:$N$6,4,FALSE),0)+IFERROR(VLOOKUP(K3,'장비 등급별 옵션'!$J$9:$N$13,4,FALSE),0)+IFERROR(VLOOKUP(L3,'장비 등급별 옵션'!$J$16:$N$20,4,FALSE),0)+IFERROR(VLOOKUP(M3,'장비 등급별 옵션'!$J$23:$N$27,4,FALSE),0)+IFERROR(VLOOKUP(N3,'장비 등급별 옵션'!$J$30:$N$34,4,FALSE),0)+IFERROR(VLOOKUP(O3,'장비 등급별 옵션'!$J$37:$N$40,4,FALSE),0) -> 130 | V3: =IFERROR(VLOOKUP(E3,'장비 등급별 옵션'!$A$2:$D$6,5,FALSE),0)+IFERROR(VLOOKUP(F3,'장비 등급별 옵션'!$A$9:$D$13,5,FALSE),0)+IFERROR(VLOOKUP(G3,'장비 등급별 옵션'!$A$16:$D$20,5,FALSE),0)+IFERROR(VLOOKUP(H3,'장비 등급별 옵션'!$A$23:$D$27,5,FALSE),0)+IFERROR(VLOOKUP(I3,'장비 등급별 옵션'!$A$30:$D$34,5,FALSE),0)+IFERROR(VLOOKUP(J3,'장비 등급별 옵션'!$J$2:$N$6,5,FALSE),0)+IFERROR(VLOOKUP(K3,'장비 등급별 옵션'!$J$9:$N$13,5,FALSE),0)+IFERROR(VLOOKUP(L3,'장비 등급별 옵션'!$J$16:$N$20,5,FALSE),0)+IFERROR(VLOOKUP(M3,'장비 등급별 옵션'!$J$23:$N$27,5,FALSE),0)+IFERROR(VLOOKUP(N3,'장비 등급별 옵션'!$J$30:$N$34,5,FALSE),0)+IFERROR(VLOOKUP(O3,'장비 등급별 옵션'!$J$37:$N$40,5,FALSE),0) -> 15 | W3: =IFERROR(VLOOKUP(E3,'장비 등급별 옵션'!$A$2:$H$6,5,FALSE),0)+IFERROR(VLOOKUP(F3,'장비 등급별 옵션'!$A$9:$H$13,5,FALSE),0)+IFERROR(VLOOKUP(G3,'장비 등급별 옵션'!$A$16:$H$20,5,FALSE),0)+IFERROR(VLOOKUP(H3,'장비 등급별 옵션'!$A$23:$H$27,5,FALSE),0)+IFERROR(VLOOKUP(I3,'장비 등급별 옵션'!$A$30:$H$34,5,FALSE),0)+IFERROR(VLOOKUP(J3,'장비 등급별 옵션'!$J$2:$R$6,6,FALSE),0)+IFERROR(VLOOKUP(K3,'장비 등급별 옵션'!$J$9:$R$13,6,FALSE),0)+IFERROR(VLOOKUP(L3,'장비 등급별 옵션'!$J$16:$R$20,6,FALSE),0)+IFERROR(VLOOKUP(M3,'장비 등급별 옵션'!$J$23:$R$27,6,FALSE),0)+IFERROR(VLOOKUP(N3,'장비 등급별 옵션'!$J$30:$R$34,6,FALSE),0)+IFERROR(VLOOKUP(O3,'장비 등급별 옵션'!$J$37:$R$40,6,FALSE),0) -> 1572 | X3: =(S3*((1.05+U3*0.0045)/1.05))/($S$25*((1.05+$U$25*0.0045)/1.05)) -> 0.50984421 | Y3: =IF($C$27="","",(1+($C$27+T3-$T$25+P3-$P$25)/100)/(1+$C$27/100)) -> 0.68264423 | Z3: =IF(OR(D3="",$D$25="",$Q$25=""),"",(1+(D3+168350+297900+TRUNC(3.08*(D3-$Q$25)+2886))/250)/(1+($D$25+168350+297900+TRUNC(3.08*($D$25-$Q$25)+2886))/250)) -> 0.99878576 | AA3: =IF(OR(C3="",X3="",Y3="",Z3=""),"",C3/X3/Y3/Z3) -> 2148.9007 | AB3: =IF(OR(C3="",$C$25=""),"",C3/$C$25) -> 0.054697225 | AC3: =IF(OR(AB3="",X3="",Y3="",Z3=""),"",AB3/X3/Y3/Z3) -> 0.15734793 | AD3: =IF(R3="","",ROUND(R3,1)) -> 8.1 | AE3: =IF(OR($C$25="",X3="",Y3="",Z3="",AC3=""),"",ROUND($C$25*X3*Y3*Z3*AC3,0)) -> 747 | AF3: =IF(OR(AE3="",C3=""),"",AE3-C3) -> 0
A4: 레어 III | B4: 910 | C4: 775 | D4: =$D$25+W4-$W$25 -> 6306 | E4: 유니크 | F4: 레어 | G4: 레어 | H4: 레어 | I4: 레어 | J4: 레어 | K4: 레어 | L4: 레어 | M4: 레어 | N4: 레어 | O4: 레어 | P4: 0 | Q4: =IF(OR(R4="",R3=""),"",((1+R4/100)/(1+R3/100)-1)*100) -> 3.7483266 | R4: =IF(OR(AC4="",$AC$2="",$R$25=""),"",(AC4/$AC$2*(1+$R$25/100)-1)*100) -> 12.100139 | S4: =(1+IFERROR(VLOOKUP(E4,'장비 등급별 옵션'!$A$2:$D$6,3,FALSE),0)/100)*(1+IFERROR(VLOOKUP(F4,'장비 등급별 옵션'!$A$9:$D$13,3,FALSE),0)/100)*(1+IFERROR(VLOOKUP(G4,'장비 등급별 옵션'!$A$16:$D$20,3,FALSE),0)/100)*(1+IFERROR(VLOOKUP(H4,'장비 등급별 옵션'!$A$23:$D$27,3,FALSE),0)/100)*(1+IFERROR(VLOOKUP(I4,'장비 등급별 옵션'!$A$30:$D$34,3,FALSE),0)/100)*(1+IFERROR(VLOOKUP(J4,'장비 등급별 옵션'!$J$2:$N$6,3,FALSE),0)/100)*(1+IFERROR(VLOOKUP(K4,'장비 등급별 옵션'!$J$9:$N$13,3,FALSE),0)/100)*(1+IFERROR(VLOOKUP(L4,'장비 등급별 옵션'!$J$16:$N$20,3,FALSE),0)/100)*(1+IFERROR(VLOOKUP(M4,'장비 등급별 옵션'!$J$23:$N$27,3,FALSE),0)/100)*(1+IFERROR(VLOOKUP(N4,'장비 등급별 옵션'!$J$30:$N$34,3,FALSE),0)/100)*(1+IFERROR(VLOOKUP(O4,'장비 등급별 옵션'!$J$37:$N$40,3,FALSE),0)/100) -> 68.080797 | T4: =IFERROR(VLOOKUP(E4,'장비 등급별 옵션'!$A$2:$D$6,2,FALSE),0)+IFERROR(VLOOKUP(F4,'장비 등급별 옵션'!$A$9:$D$13,2,FALSE),0)+IFERROR(VLOOKUP(G4,'장비 등급별 옵션'!$A$16:$D$20,2,FALSE),0)+IFERROR(VLOOKUP(H4,'장비 등급별 옵션'!$A$23:$D$27,2,FALSE),0)+IFERROR(VLOOKUP(I4,'장비 등급별 옵션'!$A$30:$D$34,2,FALSE),0)+IFERROR(VLOOKUP(J4,'장비 등급별 옵션'!$J$2:$N$6,2,FALSE),0)+IFERROR(VLOOKUP(K4,'장비 등급별 옵션'!$J$9:$N$13,2,FALSE),0)+IFERROR(VLOOKUP(L4,'장비 등급별 옵션'!$J$16:$N$20,2,FALSE),0)+IFERROR(VLOOKUP(M4,'장비 등급별 옵션'!$J$23:$N$27,2,FALSE),0)+IFERROR(VLOOKUP(N4,'장비 등급별 옵션'!$J$30:$N$34,2,FALSE),0)+IFERROR(VLOOKUP(O4,'장비 등급별 옵션'!$J$37:$N$40,2,FALSE),0) -> 24189 | U4: =IFERROR(VLOOKUP(E4,'장비 등급별 옵션'!$A$2:$D$6,4,FALSE),0)+IFERROR(VLOOKUP(F4,'장비 등급별 옵션'!$A$9:$D$13,4,FALSE),0)+IFERROR(VLOOKUP(G4,'장비 등급별 옵션'!$A$16:$D$20,4,FALSE),0)+IFERROR(VLOOKUP(H4,'장비 등급별 옵션'!$A$23:$D$27,4,FALSE),0)+IFERROR(VLOOKUP(I4,'장비 등급별 옵션'!$A$30:$D$34,4,FALSE),0)+IFERROR(VLOOKUP(J4,'장비 등급별 옵션'!$J$2:$N$6,4,FALSE),0)+IFERROR(VLOOKUP(K4,'장비 등급별 옵션'!$J$9:$N$13,4,FALSE),0)+IFERROR(VLOOKUP(L4,'장비 등급별 옵션'!$J$16:$N$20,4,FALSE),0)+IFERROR(VLOOKUP(M4,'장비 등급별 옵션'!$J$23:$N$27,4,FALSE),0)+IFERROR(VLOOKUP(N4,'장비 등급별 옵션'!$J$30:$N$34,4,FALSE),0)+IFERROR(VLOOKUP(O4,'장비 등급별 옵션'!$J$37:$N$40,4,FALSE),0) -> 130 | V4: =IFERROR(VLOOKUP(E4,'장비 등급별 옵션'!$A$2:$D$6,5,FALSE),0)+IFERROR(VLOOKUP(F4,'장비 등급별 옵션'!$A$9:$D$13,5,FALSE),0)+IFERROR(VLOOKUP(G4,'장비 등급별 옵션'!$A$16:$D$20,5,FALSE),0)+IFERROR(VLOOKUP(H4,'장비 등급별 옵션'!$A$23:$D$27,5,FALSE),0)+IFERROR(VLOOKUP(I4,'장비 등급별 옵션'!$A$30:$D$34,5,FALSE),0)+IFERROR(VLOOKUP(J4,'장비 등급별 옵션'!$J$2:$N$6,5,FALSE),0)+IFERROR(VLOOKUP(K4,'장비 등급별 옵션'!$J$9:$N$13,5,FALSE),0)+IFERROR(VLOOKUP(L4,'장비 등급별 옵션'!$J$16:$N$20,5,FALSE),0)+IFERROR(VLOOKUP(M4,'장비 등급별 옵션'!$J$23:$N$27,5,FALSE),0)+IFERROR(VLOOKUP(N4,'장비 등급별 옵션'!$J$30:$N$34,5,FALSE),0)+IFERROR(VLOOKUP(O4,'장비 등급별 옵션'!$J$37:$N$40,5,FALSE),0) -> 15 | W4: =IFERROR(VLOOKUP(E4,'장비 등급별 옵션'!$A$2:$H$6,5,FALSE),0)+IFERROR(VLOOKUP(F4,'장비 등급별 옵션'!$A$9:$H$13,5,FALSE),0)+IFERROR(VLOOKUP(G4,'장비 등급별 옵션'!$A$16:$H$20,5,FALSE),0)+IFERROR(VLOOKUP(H4,'장비 등급별 옵션'!$A$23:$H$27,5,FALSE),0)+IFERROR(VLOOKUP(I4,'장비 등급별 옵션'!$A$30:$H$34,5,FALSE),0)+IFERROR(VLOOKUP(J4,'장비 등급별 옵션'!$J$2:$R$6,6,FALSE),0)+IFERROR(VLOOKUP(K4,'장비 등급별 옵션'!$J$9:$R$13,6,FALSE),0)+IFERROR(VLOOKUP(L4,'장비 등급별 옵션'!$J$16:$R$20,6,FALSE),0)+IFERROR(VLOOKUP(M4,'장비 등급별 옵션'!$J$23:$R$27,6,FALSE),0)+IFERROR(VLOOKUP(N4,'장비 등급별 옵션'!$J$30:$R$34,6,FALSE),0)+IFERROR(VLOOKUP(O4,'장비 등급별 옵션'!$J$37:$R$40,6,FALSE),0) -> 1572 | X4: =(S4*((1.05+U4*0.0045)/1.05))/($S$25*((1.05+$U$25*0.0045)/1.05)) -> 0.50984421 | Y4: =IF($C$27="","",(1+($C$27+T4-$T$25+P4-$P$25)/100)/(1+$C$27/100)) -> 0.68264423 | Z4: =IF(OR(D4="",$D$25="",$Q$25=""),"",(1+(D4+168350+297900+TRUNC(3.08*(D4-$Q$25)+2886))/250)/(1+($D$25+168350+297900+TRUNC(3.08*($D$25-$Q$25)+2886))/250)) -> 0.99878576 | AA4: =IF(OR(C4="",X4="",Y4="",Z4=""),"",C4/X4/Y4/Z4) -> 2229.4485 | AB4: =IF(OR(C4="",$C$25=""),"",C4/$C$25) -> 0.056747456 | AC4: =IF(OR(AB4="",X4="",Y4="",Z4=""),"",AB4/X4/Y4/Z4) -> 0.16324584 | AD4: =IF(R4="","",ROUND(R4,1)) -> 12.1 | AE4: =IF(OR($C$25="",X4="",Y4="",Z4="",AC4=""),"",ROUND($C$25*X4*Y4*Z4*AC4,0)) -> 775 | AF4: =IF(OR(AE4="",C4=""),"",AE4-C4) -> 0
A5: 레어 IV | B5: 990 | C5: 802 | D5: =$D$25+W5-$W$25 -> 6306 | E5: 유니크 | F5: 레어 | G5: 레어 | H5: 레어 | I5: 레어 | J5: 레어 | K5: 레어 | L5: 레어 | M5: 레어 | N5: 레어 | O5: 레어 | P5: 0 | Q5: =IF(OR(R5="",R4=""),"",((1+R5/100)/(1+R4/100)-1)*100) -> 3.483871 | R5: =IF(OR(AC5="",$AC$2="",$R$25=""),"",(AC5/$AC$2*(1+$R$25/100)-1)*100) -> 16.005563 | S5: =(1+IFERROR(VLOOKUP(E5,'장비 등급별 옵션'!$A$2:$D$6,3,FALSE),0)/100)*(1+IFERROR(VLOOKUP(F5,'장비 등급별 옵션'!$A$9:$D$13,3,FALSE),0)/100)*(1+IFERROR(VLOOKUP(G5,'장비 등급별 옵션'!$A$16:$D$20,3,FALSE),0)/100)*(1+IFERROR(VLOOKUP(H5,'장비 등급별 옵션'!$A$23:$D$27,3,FALSE),0)/100)*(1+IFERROR(VLOOKUP(I5,'장비 등급별 옵션'!$A$30:$D$34,3,FALSE),0)/100)*(1+IFERROR(VLOOKUP(J5,'장비 등급별 옵션'!$J$2:$N$6,3,FALSE),0)/100)*(1+IFERROR(VLOOKUP(K5,'장비 등급별 옵션'!$J$9:$N$13,3,FALSE),0)/100)*(1+IFERROR(VLOOKUP(L5,'장비 등급별 옵션'!$J$16:$N$20,3,FALSE),0)/100)*(1+IFERROR(VLOOKUP(M5,'장비 등급별 옵션'!$J$23:$N$27,3,FALSE),0)/100)*(1+IFERROR(VLOOKUP(N5,'장비 등급별 옵션'!$J$30:$N$34,3,FALSE),0)/100)*(1+IFERROR(VLOOKUP(O5,'장비 등급별 옵션'!$J$37:$N$40,3,FALSE),0)/100) -> 68.080797 | T5: =IFERROR(VLOOKUP(E5,'장비 등급별 옵션'!$A$2:$D$6,2,FALSE),0)+IFERROR(VLOOKUP(F5,'장비 등급별 옵션'!$A$9:$D$13,2,FALSE),0)+IFERROR(VLOOKUP(G5,'장비 등급별 옵션'!$A$16:$D$20,2,FALSE),0)+IFERROR(VLOOKUP(H5,'장비 등급별 옵션'!$A$23:$D$27,2,FALSE),0)+IFERROR(VLOOKUP(I5,'장비 등급별 옵션'!$A$30:$D$34,2,FALSE),0)+IFERROR(VLOOKUP(J5,'장비 등급별 옵션'!$J$2:$N$6,2,FALSE),0)+IFERROR(VLOOKUP(K5,'장비 등급별 옵션'!$J$9:$N$13,2,FALSE),0)+IFERROR(VLOOKUP(L5,'장비 등급별 옵션'!$J$16:$N$20,2,FALSE),0)+IFERROR(VLOOKUP(M5,'장비 등급별 옵션'!$J$23:$N$27,2,FALSE),0)+IFERROR(VLOOKUP(N5,'장비 등급별 옵션'!$J$30:$N$34,2,FALSE),0)+IFERROR(VLOOKUP(O5,'장비 등급별 옵션'!$J$37:$N$40,2,FALSE),0) -> 24189 | U5: =IFERROR(VLOOKUP(E5,'장비 등급별 옵션'!$A$2:$D$6,4,FALSE),0)+IFERROR(VLOOKUP(F5,'장비 등급별 옵션'!$A$9:$D$13,4,FALSE),0)+IFERROR(VLOOKUP(G5,'장비 등급별 옵션'!$A$16:$D$20,4,FALSE),0)+IFERROR(VLOOKUP(H5,'장비 등급별 옵션'!$A$23:$D$27,4,FALSE),0)+IFERROR(VLOOKUP(I5,'장비 등급별 옵션'!$A$30:$D$34,4,FALSE),0)+IFERROR(VLOOKUP(J5,'장비 등급별 옵션'!$J$2:$N$6,4,FALSE),0)+IFERROR(VLOOKUP(K5,'장비 등급별 옵션'!$J$9:$N$13,4,FALSE),0)+IFERROR(VLOOKUP(L5,'장비 등급별 옵션'!$J$16:$N$20,4,FALSE),0)+IFERROR(VLOOKUP(M5,'장비 등급별 옵션'!$J$23:$N$27,4,FALSE),0)+IFERROR(VLOOKUP(N5,'장비 등급별 옵션'!$J$30:$N$34,4,FALSE),0)+IFERROR(VLOOKUP(O5,'장비 등급별 옵션'!$J$37:$N$40,4,FALSE),0) -> 130 | V5: =IFERROR(VLOOKUP(E5,'장비 등급별 옵션'!$A$2:$D$6,5,FALSE),0)+IFERROR(VLOOKUP(F5,'장비 등급별 옵션'!$A$9:$D$13,5,FALSE),0)+IFERROR(VLOOKUP(G5,'장비 등급별 옵션'!$A$16:$D$20,5,FALSE),0)+IFERROR(VLOOKUP(H5,'장비 등급별 옵션'!$A$23:$D$27,5,FALSE),0)+IFERROR(VLOOKUP(I5,'장비 등급별 옵션'!$A$30:$D$34,5,FALSE),0)+IFERROR(VLOOKUP(J5,'장비 등급별 옵션'!$J$2:$N$6,5,FALSE),0)+IFERROR(VLOOKUP(K5,'장비 등급별 옵션'!$J$9:$N$13,5,FALSE),0)+IFERROR(VLOOKUP(L5,'장비 등급별 옵션'!$J$16:$N$20,5,FALSE),0)+IFERROR(VLOOKUP(M5,'장비 등급별 옵션'!$J$23:$N$27,5,FALSE),0)+IFERROR(VLOOKUP(N5,'장비 등급별 옵션'!$J$30:$N$34,5,FALSE),0)+IFERROR(VLOOKUP(O5,'장비 등급별 옵션'!$J$37:$N$40,5,FALSE),0) -> 15 | W5: =IFERROR(VLOOKUP(E5,'장비 등급별 옵션'!$A$2:$H$6,5,FALSE),0)+IFERROR(VLOOKUP(F5,'장비 등급별 옵션'!$A$9:$H$13,5,FALSE),0)+IFERROR(VLOOKUP(G5,'장비 등급별 옵션'!$A$16:$H$20,5,FALSE),0)+IFERROR(VLOOKUP(H5,'장비 등급별 옵션'!$A$23:$H$27,5,FALSE),0)+IFERROR(VLOOKUP(I5,'장비 등급별 옵션'!$A$30:$H$34,5,FALSE),0)+IFERROR(VLOOKUP(J5,'장비 등급별 옵션'!$J$2:$R$6,6,FALSE),0)+IFERROR(VLOOKUP(K5,'장비 등급별 옵션'!$J$9:$R$13,6,FALSE),0)+IFERROR(VLOOKUP(L5,'장비 등급별 옵션'!$J$16:$R$20,6,FALSE),0)+IFERROR(VLOOKUP(M5,'장비 등급별 옵션'!$J$23:$R$27,6,FALSE),0)+IFERROR(VLOOKUP(N5,'장비 등급별 옵션'!$J$30:$R$34,6,FALSE),0)+IFERROR(VLOOKUP(O5,'장비 등급별 옵션'!$J$37:$R$40,6,FALSE),0) -> 1572 | X5: =(S5*((1.05+U5*0.0045)/1.05))/($S$25*((1.05+$U$25*0.0045)/1.05)) -> 0.50984421 | Y5: =IF($C$27="","",(1+($C$27+T5-$T$25+P5-$P$25)/100)/(1+$C$27/100)) -> 0.68264423 | Z5: =IF(OR(D5="",$D$25="",$Q$25=""),"",(1+(D5+168350+297900+TRUNC(3.08*(D5-$Q$25)+2886))/250)/(1+($D$25+168350+297900+TRUNC(3.08*($D$25-$Q$25)+2886))/250)) -> 0.99878576 | AA5: =IF(OR(C5="",X5="",Y5="",Z5=""),"",C5/X5/Y5/Z5) -> 2307.1196 | AB5: =IF(OR(C5="",$C$25=""),"",C5/$C$25) -> 0.058724464 | AC5: =IF(OR(AB5="",X5="",Y5="",Z5=""),"",AB5/X5/Y5/Z5) -> 0.16893312 | AD5: =IF(R5="","",ROUND(R5,1)) -> 16 | AE5: =IF(OR($C$25="",X5="",Y5="",Z5="",AC5=""),"",ROUND($C$25*X5*Y5*Z5*AC5,0)) -> 802 | AF5: =IF(OR(AE5="",C5=""),"",AE5-C5) -> 0
A6: 레어 V | B6: 1070 | C6: 830 | D6: =$D$25+W6-$W$25 -> 6306 | E6: 유니크 | F6: 레어 | G6: 레어 | H6: 레어 | I6: 레어 | J6: 레어 | K6: 레어 | L6: 레어 | M6: 레어 | N6: 레어 | O6: 레어 | P6: 0 | Q6: =IF(OR(R6="",R5=""),"",((1+R6/100)/(1+R5/100)-1)*100) -> 3.4912718 | R6: =IF(OR(AC6="",$AC$2="",$R$25=""),"",(AC6/$AC$2*(1+$R$25/100)-1)*100) -> 20.055633 | S6: =(1+IFERROR(VLOOKUP(E6,'장비 등급별 옵션'!$A$2:$D$6,3,FALSE),0)/100)*(1+IFERROR(VLOOKUP(F6,'장비 등급별 옵션'!$A$9:$D$13,3,FALSE),0)/100)*(1+IFERROR(VLOOKUP(G6,'장비 등급별 옵션'!$A$16:$D$20,3,FALSE),0)/100)*(1+IFERROR(VLOOKUP(H6,'장비 등급별 옵션'!$A$23:$D$27,3,FALSE),0)/100)*(1+IFERROR(VLOOKUP(I6,'장비 등급별 옵션'!$A$30:$D$34,3,FALSE),0)/100)*(1+IFERROR(VLOOKUP(J6,'장비 등급별 옵션'!$J$2:$N$6,3,FALSE),0)/100)*(1+IFERROR(VLOOKUP(K6,'장비 등급별 옵션'!$J$9:$N$13,3,FALSE),0)/100)*(1+IFERROR(VLOOKUP(L6,'장비 등급별 옵션'!$J$16:$N$20,3,FALSE),0)/100)*(1+IFERROR(VLOOKUP(M6,'장비 등급별 옵션'!$J$23:$N$27,3,FALSE),0)/100)*(1+IFERROR(VLOOKUP(N6,'장비 등급별 옵션'!$J$30:$N$34,3,FALSE),0)/100)*(1+IFERROR(VLOOKUP(O6,'장비 등급별 옵션'!$J$37:$N$40,3,FALSE),0)/100) -> 68.080797 | T6: =IFERROR(VLOOKUP(E6,'장비 등급별 옵션'!$A$2:$D$6,2,FALSE),0)+IFERROR(VLOOKUP(F6,'장비 등급별 옵션'!$A$9:$D$13,2,FALSE),0)+IFERROR(VLOOKUP(G6,'장비 등급별 옵션'!$A$16:$D$20,2,FALSE),0)+IFERROR(VLOOKUP(H6,'장비 등급별 옵션'!$A$23:$D$27,2,FALSE),0)+IFERROR(VLOOKUP(I6,'장비 등급별 옵션'!$A$30:$D$34,2,FALSE),0)+IFERROR(VLOOKUP(J6,'장비 등급별 옵션'!$J$2:$N$6,2,FALSE),0)+IFERROR(VLOOKUP(K6,'장비 등급별 옵션'!$J$9:$N$13,2,FALSE),0)+IFERROR(VLOOKUP(L6,'장비 등급별 옵션'!$J$16:$N$20,2,FALSE),0)+IFERROR(VLOOKUP(M6,'장비 등급별 옵션'!$J$23:$N$27,2,FALSE),0)+IFERROR(VLOOKUP(N6,'장비 등급별 옵션'!$J$30:$N$34,2,FALSE),0)+IFERROR(VLOOKUP(O6,'장비 등급별 옵션'!$J$37:$N$40,2,FALSE),0) -> 24189 | U6: =IFERROR(VLOOKUP(E6,'장비 등급별 옵션'!$A$2:$D$6,4,FALSE),0)+IFERROR(VLOOKUP(F6,'장비 등급별 옵션'!$A$9:$D$13,4,FALSE),0)+IFERROR(VLOOKUP(G6,'장비 등급별 옵션'!$A$16:$D$20,4,FALSE),0)+IFERROR(VLOOKUP(H6,'장비 등급별 옵션'!$A$23:$D$27,4,FALSE),0)+IFERROR(VLOOKUP(I6,'장비 등급별 옵션'!$A$30:$D$34,4,FALSE),0)+IFERROR(VLOOKUP(J6,'장비 등급별 옵션'!$J$2:$N$6,4,FALSE),0)+IFERROR(VLOOKUP(K6,'장비 등급별 옵션'!$J$9:$N$13,4,FALSE),0)+IFERROR(VLOOKUP(L6,'장비 등급별 옵션'!$J$16:$N$20,4,FALSE),0)+IFERROR(VLOOKUP(M6,'장비 등급별 옵션'!$J$23:$N$27,4,FALSE),0)+IFERROR(VLOOKUP(N6,'장비 등급별 옵션'!$J$30:$N$34,4,FALSE),0)+IFERROR(VLOOKUP(O6,'장비 등급별 옵션'!$J$37:$N$40,4,FALSE),0) -> 130 | V6: =IFERROR(VLOOKUP(E6,'장비 등급별 옵션'!$A$2:$D$6,5,FALSE),0)+IFERROR(VLOOKUP(F6,'장비 등급별 옵션'!$A$9:$D$13,5,FALSE),0)+IFERROR(VLOOKUP(G6,'장비 등급별 옵션'!$A$16:$D$20,5,FALSE),0)+IFERROR(VLOOKUP(H6,'장비 등급별 옵션'!$A$23:$D$27,5,FALSE),0)+IFERROR(VLOOKUP(I6,'장비 등급별 옵션'!$A$30:$D$34,5,FALSE),0)+IFERROR(VLOOKUP(J6,'장비 등급별 옵션'!$J$2:$N$6,5,FALSE),0)+IFERROR(VLOOKUP(K6,'장비 등급별 옵션'!$J$9:$N$13,5,FALSE),0)+IFERROR(VLOOKUP(L6,'장비 등급별 옵션'!$J$16:$N$20,5,FALSE),0)+IFERROR(VLOOKUP(M6,'장비 등급별 옵션'!$J$23:$N$27,5,FALSE),0)+IFERROR(VLOOKUP(N6,'장비 등급별 옵션'!$J$30:$N$34,5,FALSE),0)+IFERROR(VLOOKUP(O6,'장비 등급별 옵션'!$J$37:$N$40,5,FALSE),0) -> 15 | W6: =IFERROR(VLOOKUP(E6,'장비 등급별 옵션'!$A$2:$H$6,5,FALSE),0)+IFERROR(VLOOKUP(F6,'장비 등급별 옵션'!$A$9:$H$13,5,FALSE),0)+IFERROR(VLOOKUP(G6,'장비 등급별 옵션'!$A$16:$H$20,5,FALSE),0)+IFERROR(VLOOKUP(H6,'장비 등급별 옵션'!$A$23:$H$27,5,FALSE),0)+IFERROR(VLOOKUP(I6,'장비 등급별 옵션'!$A$30:$H$34,5,FALSE),0)+IFERROR(VLOOKUP(J6,'장비 등급별 옵션'!$J$2:$R$6,6,FALSE),0)+IFERROR(VLOOKUP(K6,'장비 등급별 옵션'!$J$9:$R$13,6,FALSE),0)+IFERROR(VLOOKUP(L6,'장비 등급별 옵션'!$J$16:$R$20,6,FALSE),0)+IFERROR(VLOOKUP(M6,'장비 등급별 옵션'!$J$23:$R$27,6,FALSE),0)+IFERROR(VLOOKUP(N6,'장비 등급별 옵션'!$J$30:$R$34,6,FALSE),0)+IFERROR(VLOOKUP(O6,'장비 등급별 옵션'!$J$37:$R$40,6,FALSE),0) -> 1572 | X6: =(S6*((1.05+U6*0.0045)/1.05))/($S$25*((1.05+$U$25*0.0045)/1.05)) -> 0.50984421 | Y6: =IF($C$27="","",(1+($C$27+T6-$T$25+P6-$P$25)/100)/(1+$C$27/100)) -> 0.68264423 | Z6: =IF(OR(D6="",$D$25="",$Q$25=""),"",(1+(D6+168350+297900+TRUNC(3.08*(D6-$Q$25)+2886))/250)/(1+($D$25+168350+297900+TRUNC(3.08*($D$25-$Q$25)+2886))/250)) -> 0.99878576 | AA6: =IF(OR(C6="",X6="",Y6="",Z6=""),"",C6/X6/Y6/Z6) -> 2387.6674 | AB6: =IF(OR(C6="",$C$25=""),"",C6/$C$25) -> 0.060774694 | AC6: =IF(OR(AB6="",X6="",Y6="",Z6=""),"",AB6/X6/Y6/Z6) -> 0.17483103 | AD6: =IF(R6="","",ROUND(R6,1)) -> 20.1 | AE6: =IF(OR($C$25="",X6="",Y6="",Z6="",AC6=""),"",ROUND($C$25*X6*Y6*Z6*AC6,0)) -> 830 | AF6: =IF(OR(AE6="",C6=""),"",AE6-C6) -> 0
A7: 유니크 I | B7: 1200 | C7: 1472 | D7: =$D$25+W7-$W$25 -> 6322 | E7: 유니크 | F7: 유니크 | G7: 유니크 | H7: 유니크 | I7: 유니크 | J7: 유니크 | K7: 유니크 | L7: 유니크 | M7: 유니크 | N7: 유니크 | O7: 레어 | P7: 0 | Q7: =IF(OR(R7="",R6=""),"",((1+R7/100)/(1+R6/100)-1)*100) -> 23.480211 | R7: =IF(OR(AC7="",$AC$2="",$R$25=""),"",(AC7/$AC$2*(1+$R$25/100)-1)*100) -> 48.244949 | S7: =(1+IFERROR(VLOOKUP(E7,'장비 등급별 옵션'!$A$2:$D$6,3,FALSE),0)/100)*(1+IFERROR(VLOOKUP(F7,'장비 등급별 옵션'!$A$9:$D$13,3,FALSE),0)/100)*(1+IFERROR(VLOOKUP(G7,'장비 등급별 옵션'!$A$16:$D$20,3,FALSE),0)/100)*(1+IFERROR(VLOOKUP(H7,'장비 등급별 옵션'!$A$23:$D$27,3,FALSE),0)/100)*(1+IFERROR(VLOOKUP(I7,'장비 등급별 옵션'!$A$30:$D$34,3,FALSE),0)/100)*(1+IFERROR(VLOOKUP(J7,'장비 등급별 옵션'!$J$2:$N$6,3,FALSE),0)/100)*(1+IFERROR(VLOOKUP(K7,'장비 등급별 옵션'!$J$9:$N$13,3,FALSE),0)/100)*(1+IFERROR(VLOOKUP(L7,'장비 등급별 옵션'!$J$16:$N$20,3,FALSE),0)/100)*(1+IFERROR(VLOOKUP(M7,'장비 등급별 옵션'!$J$23:$N$27,3,FALSE),0)/100)*(1+IFERROR(VLOOKUP(N7,'장비 등급별 옵션'!$J$30:$N$34,3,FALSE),0)/100)*(1+IFERROR(VLOOKUP(O7,'장비 등급별 옵션'!$J$37:$N$40,3,FALSE),0)/100) -> 81.362854 | T7: =IFERROR(VLOOKUP(E7,'장비 등급별 옵션'!$A$2:$D$6,2,FALSE),0)+IFERROR(VLOOKUP(F7,'장비 등급별 옵션'!$A$9:$D$13,2,FALSE),0)+IFERROR(VLOOKUP(G7,'장비 등급별 옵션'!$A$16:$D$20,2,FALSE),0)+IFERROR(VLOOKUP(H7,'장비 등급별 옵션'!$A$23:$D$27,2,FALSE),0)+IFERROR(VLOOKUP(I7,'장비 등급별 옵션'!$A$30:$D$34,2,FALSE),0)+IFERROR(VLOOKUP(J7,'장비 등급별 옵션'!$J$2:$N$6,2,FALSE),0)+IFERROR(VLOOKUP(K7,'장비 등급별 옵션'!$J$9:$N$13,2,FALSE),0)+IFERROR(VLOOKUP(L7,'장비 등급별 옵션'!$J$16:$N$20,2,FALSE),0)+IFERROR(VLOOKUP(M7,'장비 등급별 옵션'!$J$23:$N$27,2,FALSE),0)+IFERROR(VLOOKUP(N7,'장비 등급별 옵션'!$J$30:$N$34,2,FALSE),0)+IFERROR(VLOOKUP(O7,'장비 등급별 옵션'!$J$37:$N$40,2,FALSE),0) -> 33990 | U7: =IFERROR(VLOOKUP(E7,'장비 등급별 옵션'!$A$2:$D$6,4,FALSE),0)+IFERROR(VLOOKUP(F7,'장비 등급별 옵션'!$A$9:$D$13,4,FALSE),0)+IFERROR(VLOOKUP(G7,'장비 등급별 옵션'!$A$16:$D$20,4,FALSE),0)+IFERROR(VLOOKUP(H7,'장비 등급별 옵션'!$A$23:$D$27,4,FALSE),0)+IFERROR(VLOOKUP(I7,'장비 등급별 옵션'!$A$30:$D$34,4,FALSE),0)+IFERROR(VLOOKUP(J7,'장비 등급별 옵션'!$J$2:$N$6,4,FALSE),0)+IFERROR(VLOOKUP(K7,'장비 등급별 옵션'!$J$9:$N$13,4,FALSE),0)+IFERROR(VLOOKUP(L7,'장비 등급별 옵션'!$J$16:$N$20,4,FALSE),0)+IFERROR(VLOOKUP(M7,'장비 등급별 옵션'!$J$23:$N$27,4,FALSE),0)+IFERROR(VLOOKUP(N7,'장비 등급별 옵션'!$J$30:$N$34,4,FALSE),0)+IFERROR(VLOOKUP(O7,'장비 등급별 옵션'!$J$37:$N$40,4,FALSE),0) -> 130 | V7: =IFERROR(VLOOKUP(E7,'장비 등급별 옵션'!$A$2:$D$6,5,FALSE),0)+IFERROR(VLOOKUP(F7,'장비 등급별 옵션'!$A$9:$D$13,5,FALSE),0)+IFERROR(VLOOKUP(G7,'장비 등급별 옵션'!$A$16:$D$20,5,FALSE),0)+IFERROR(VLOOKUP(H7,'장비 등급별 옵션'!$A$23:$D$27,5,FALSE),0)+IFERROR(VLOOKUP(I7,'장비 등급별 옵션'!$A$30:$D$34,5,FALSE),0)+IFERROR(VLOOKUP(J7,'장비 등급별 옵션'!$J$2:$N$6,5,FALSE),0)+IFERROR(VLOOKUP(K7,'장비 등급별 옵션'!$J$9:$N$13,5,FALSE),0)+IFERROR(VLOOKUP(L7,'장비 등급별 옵션'!$J$16:$N$20,5,FALSE),0)+IFERROR(VLOOKUP(M7,'장비 등급별 옵션'!$J$23:$N$27,5,FALSE),0)+IFERROR(VLOOKUP(N7,'장비 등급별 옵션'!$J$30:$N$34,5,FALSE),0)+IFERROR(VLOOKUP(O7,'장비 등급별 옵션'!$J$37:$N$40,5,FALSE),0) -> 15 | W7: =IFERROR(VLOOKUP(E7,'장비 등급별 옵션'!$A$2:$H$6,5,FALSE),0)+IFERROR(VLOOKUP(F7,'장비 등급별 옵션'!$A$9:$H$13,5,FALSE),0)+IFERROR(VLOOKUP(G7,'장비 등급별 옵션'!$A$16:$H$20,5,FALSE),0)+IFERROR(VLOOKUP(H7,'장비 등급별 옵션'!$A$23:$H$27,5,FALSE),0)+IFERROR(VLOOKUP(I7,'장비 등급별 옵션'!$A$30:$H$34,5,FALSE),0)+IFERROR(VLOOKUP(J7,'장비 등급별 옵션'!$J$2:$R$6,6,FALSE),0)+IFERROR(VLOOKUP(K7,'장비 등급별 옵션'!$J$9:$R$13,6,FALSE),0)+IFERROR(VLOOKUP(L7,'장비 등급별 옵션'!$J$16:$R$20,6,FALSE),0)+IFERROR(VLOOKUP(M7,'장비 등급별 옵션'!$J$23:$R$27,6,FALSE),0)+IFERROR(VLOOKUP(N7,'장비 등급별 옵션'!$J$30:$R$34,6,FALSE),0)+IFERROR(VLOOKUP(O7,'장비 등급별 옵션'!$J$37:$R$40,6,FALSE),0) -> 1588 | X7: =(S7*((1.05+U7*0.0045)/1.05))/($S$25*((1.05+$U$25*0.0045)/1.05)) -> 0.60931103 | Y7: =IF($C$27="","",(1+($C$27+T7-$T$25+P7-$P$25)/100)/(1+$C$27/100)) -> 0.82029099 | Z7: =IF(OR(D7="",$D$25="",$Q$25=""),"",(1+(D7+168350+297900+TRUNC(3.08*(D7-$Q$25)+2886))/250)/(1+($D$25+168350+297900+TRUNC(3.08*($D$25-$Q$25)+2886))/250)) -> 0.99891753 | AA7: =IF(OR(C7="",X7="",Y7="",Z7=""),"",C7/X7/Y7/Z7) -> 2948.2968 | AB7: =IF(OR(C7="",$C$25=""),"",C7/$C$25) -> 0.10778355 | AC7: =IF(OR(AB7="",X7="",Y7="",Z7=""),"",AB7/X7/Y7/Z7) -> 0.21588173 | AD7: =IF(R7="","",ROUND(R7,1)) -> 48.2 | AE7: =IF(OR($C$25="",X7="",Y7="",Z7="",AC7=""),"",ROUND($C$25*X7*Y7*Z7*AC7,0)) -> 1472 | AF7: =IF(OR(AE7="",C7=""),"",AE7-C7) -> 0
A8: 유니크 II | B8: 1285 | C8: 1781 | D8: =$D$25+W8-$W$25 -> 6326 | E8: 레전더리 | F8: 유니크 | G8: 유니크 | H8: 유니크 | I8: 유니크 | J8: 유니크 | K8: 유니크 | L8: 유니크 | M8: 유니크 | N8: 유니크 | O8: 유니크 | P8: 433 | Q8: =IF(OR(R8="",R7=""),"",((1+R8/100)/(1+R7/100)-1)*100) -> 6.7796794 | R8: =IF(OR(AC8="",$AC$2="",$R$25=""),"",(AC8/$AC$2*(1+$R$25/100)-1)*100) -> 58.295482 | S8: =(1+IFERROR(VLOOKUP(E8,'장비 등급별 옵션'!$A$2:$D$6,3,FALSE),0)/100)*(1+IFERROR(VLOOKUP(F8,'장비 등급별 옵션'!$A$9:$D$13,3,FALSE),0)/100)*(1+IFERROR(VLOOKUP(G8,'장비 등급별 옵션'!$A$16:$D$20,3,FALSE),0)/100)*(1+IFERROR(VLOOKUP(H8,'장비 등급별 옵션'!$A$23:$D$27,3,FALSE),0)/100)*(1+IFERROR(VLOOKUP(I8,'장비 등급별 옵션'!$A$30:$D$34,3,FALSE),0)/100)*(1+IFERROR(VLOOKUP(J8,'장비 등급별 옵션'!$J$2:$N$6,3,FALSE),0)/100)*(1+IFERROR(VLOOKUP(K8,'장비 등급별 옵션'!$J$9:$N$13,3,FALSE),0)/100)*(1+IFERROR(VLOOKUP(L8,'장비 등급별 옵션'!$J$16:$N$20,3,FALSE),0)/100)*(1+IFERROR(VLOOKUP(M8,'장비 등급별 옵션'!$J$23:$N$27,3,FALSE),0)/100)*(1+IFERROR(VLOOKUP(N8,'장비 등급별 옵션'!$J$30:$N$34,3,FALSE),0)/100)*(1+IFERROR(VLOOKUP(O8,'장비 등급별 옵션'!$J$37:$N$40,3,FALSE),0)/100) -> 89.847838 | T8: =IFERROR(VLOOKUP(E8,'장비 등급별 옵션'!$A$2:$D$6,2,FALSE),0)+IFERROR(VLOOKUP(F8,'장비 등급별 옵션'!$A$9:$D$13,2,FALSE),0)+IFERROR(VLOOKUP(G8,'장비 등급별 옵션'!$A$16:$D$20,2,FALSE),0)+IFERROR(VLOOKUP(H8,'장비 등급별 옵션'!$A$23:$D$27,2,FALSE),0)+IFERROR(VLOOKUP(I8,'장비 등급별 옵션'!$A$30:$D$34,2,FALSE),0)+IFERROR(VLOOKUP(J8,'장비 등급별 옵션'!$J$2:$N$6,2,FALSE),0)+IFERROR(VLOOKUP(K8,'장비 등급별 옵션'!$J$9:$N$13,2,FALSE),0)+IFERROR(VLOOKUP(L8,'장비 등급별 옵션'!$J$16:$N$20,2,FALSE),0)+IFERROR(VLOOKUP(M8,'장비 등급별 옵션'!$J$23:$N$27,2,FALSE),0)+IFERROR(VLOOKUP(N8,'장비 등급별 옵션'!$J$30:$N$34,2,FALSE),0)+IFERROR(VLOOKUP(O8,'장비 등급별 옵션'!$J$37:$N$40,2,FALSE),0) -> 35079 | U8: =IFERROR(VLOOKUP(E8,'장비 등급별 옵션'!$A$2:$D$6,4,FALSE),0)+IFERROR(VLOOKUP(F8,'장비 등급별 옵션'!$A$9:$D$13,4,FALSE),0)+IFERROR(VLOOKUP(G8,'장비 등급별 옵션'!$A$16:$D$20,4,FALSE),0)+IFERROR(VLOOKUP(H8,'장비 등급별 옵션'!$A$23:$D$27,4,FALSE),0)+IFERROR(VLOOKUP(I8,'장비 등급별 옵션'!$A$30:$D$34,4,FALSE),0)+IFERROR(VLOOKUP(J8,'장비 등급별 옵션'!$J$2:$N$6,4,FALSE),0)+IFERROR(VLOOKUP(K8,'장비 등급별 옵션'!$J$9:$N$13,4,FALSE),0)+IFERROR(VLOOKUP(L8,'장비 등급별 옵션'!$J$16:$N$20,4,FALSE),0)+IFERROR(VLOOKUP(M8,'장비 등급별 옵션'!$J$23:$N$27,4,FALSE),0)+IFERROR(VLOOKUP(N8,'장비 등급별 옵션'!$J$30:$N$34,4,FALSE),0)+IFERROR(VLOOKUP(O8,'장비 등급별 옵션'!$J$37:$N$40,4,FALSE),0) -> 130 | V8: =IFERROR(VLOOKUP(E8,'장비 등급별 옵션'!$A$2:$D$6,5,FALSE),0)+IFERROR(VLOOKUP(F8,'장비 등급별 옵션'!$A$9:$D$13,5,FALSE),0)+IFERROR(VLOOKUP(G8,'장비 등급별 옵션'!$A$16:$D$20,5,FALSE),0)+IFERROR(VLOOKUP(H8,'장비 등급별 옵션'!$A$23:$D$27,5,FALSE),0)+IFERROR(VLOOKUP(I8,'장비 등급별 옵션'!$A$30:$D$34,5,FALSE),0)+IFERROR(VLOOKUP(J8,'장비 등급별 옵션'!$J$2:$N$6,5,FALSE),0)+IFERROR(VLOOKUP(K8,'장비 등급별 옵션'!$J$9:$N$13,5,FALSE),0)+IFERROR(VLOOKUP(L8,'장비 등급별 옵션'!$J$16:$N$20,5,FALSE),0)+IFERROR(VLOOKUP(M8,'장비 등급별 옵션'!$J$23:$N$27,5,FALSE),0)+IFERROR(VLOOKUP(N8,'장비 등급별 옵션'!$J$30:$N$34,5,FALSE),0)+IFERROR(VLOOKUP(O8,'장비 등급별 옵션'!$J$37:$N$40,5,FALSE),0) -> 15 | W8: =IFERROR(VLOOKUP(E8,'장비 등급별 옵션'!$A$2:$H$6,5,FALSE),0)+IFERROR(VLOOKUP(F8,'장비 등급별 옵션'!$A$9:$H$13,5,FALSE),0)+IFERROR(VLOOKUP(G8,'장비 등급별 옵션'!$A$16:$H$20,5,FALSE),0)+IFERROR(VLOOKUP(H8,'장비 등급별 옵션'!$A$23:$H$27,5,FALSE),0)+IFERROR(VLOOKUP(I8,'장비 등급별 옵션'!$A$30:$H$34,5,FALSE),0)+IFERROR(VLOOKUP(J8,'장비 등급별 옵션'!$J$2:$R$6,6,FALSE),0)+IFERROR(VLOOKUP(K8,'장비 등급별 옵션'!$J$9:$R$13,6,FALSE),0)+IFERROR(VLOOKUP(L8,'장비 등급별 옵션'!$J$16:$R$20,6,FALSE),0)+IFERROR(VLOOKUP(M8,'장비 등급별 옵션'!$J$23:$R$27,6,FALSE),0)+IFERROR(VLOOKUP(N8,'장비 등급별 옵션'!$J$30:$R$34,6,FALSE),0)+IFERROR(VLOOKUP(O8,'장비 등급별 옵션'!$J$37:$R$40,6,FALSE),0) -> 1592 | X8: =(S8*((1.05+U8*0.0045)/1.05))/($S$25*((1.05+$U$25*0.0045)/1.05)) -> 0.67285346 | Y8: =IF($C$27="","",(1+($C$27+T8-$T$25+P8-$P$25)/100)/(1+$C$27/100)) -> 0.8416662 | Z8: =IF(OR(D8="",$D$25="",$Q$25=""),"",(1+(D8+168350+297900+TRUNC(3.08*(D8-$Q$25)+2886))/250)/(1+($D$25+168350+297900+TRUNC(3.08*($D$25-$Q$25)+2886))/250)) -> 0.99894996 | AA8: =IF(OR(C8="",X8="",Y8="",Z8=""),"",C8/X8/Y8/Z8) -> 3148.1818 | AB8: =IF(OR(C8="",$C$25=""),"",C8/$C$25) -> 0.13040931 | AC8: =IF(OR(AB8="",X8="",Y8="",Z8=""),"",AB8/X8/Y8/Z8) -> 0.23051782 | AD8: =IF(R8="","",ROUND(R8,1)) -> 58.3 | AE8: =IF(OR($C$25="",X8="",Y8="",Z8="",AC8=""),"",ROUND($C$25*X8*Y8*Z8*AC8,0)) -> 1781 | AF8: =IF(OR(AE8="",C8=""),"",AE8-C8) -> 0
A9: 유니크 III | B9: 1370 | C9: 2099 | D9: =$D$25+W9-$W$25 -> 6328 | E9: 레전더리 | F9: 레전더리 | G9: 레전더리 | H9: 유니크 | I9: 유니크 | J9: 유니크 | K9: 유니크 | L9: 유니크 | M9: 유니크 | N9: 유니크 | O9: 유니크 | P9: 1299 | Q9: =IF(OR(R9="",R8=""),"",((1+R9/100)/(1+R8/100)-1)*100) -> 13.822436 | R9: =IF(OR(AC9="",$AC$2="",$R$25=""),"",(AC9/$AC$2*(1+$R$25/100)-1)*100) -> 80.175773 | S9: =(1+IFERROR(VLOOKUP(E9,'장비 등급별 옵션'!$A$2:$D$6,3,FALSE),0)/100)*(1+IFERROR(VLOOKUP(F9,'장비 등급별 옵션'!$A$9:$D$13,3,FALSE),0)/100)*(1+IFERROR(VLOOKUP(G9,'장비 등급별 옵션'!$A$16:$D$20,3,FALSE),0)/100)*(1+IFERROR(VLOOKUP(H9,'장비 등급별 옵션'!$A$23:$D$27,3,FALSE),0)/100)*(1+IFERROR(VLOOKUP(I9,'장비 등급별 옵션'!$A$30:$D$34,3,FALSE),0)/100)*(1+IFERROR(VLOOKUP(J9,'장비 등급별 옵션'!$J$2:$N$6,3,FALSE),0)/100)*(1+IFERROR(VLOOKUP(K9,'장비 등급별 옵션'!$J$9:$N$13,3,FALSE),0)/100)*(1+IFERROR(VLOOKUP(L9,'장비 등급별 옵션'!$J$16:$N$20,3,FALSE),0)/100)*(1+IFERROR(VLOOKUP(M9,'장비 등급별 옵션'!$J$23:$N$27,3,FALSE),0)/100)*(1+IFERROR(VLOOKUP(N9,'장비 등급별 옵션'!$J$30:$N$34,3,FALSE),0)/100)*(1+IFERROR(VLOOKUP(O9,'장비 등급별 옵션'!$J$37:$N$40,3,FALSE),0)/100) -> 91.704468 | T9: =IFERROR(VLOOKUP(E9,'장비 등급별 옵션'!$A$2:$D$6,2,FALSE),0)+IFERROR(VLOOKUP(F9,'장비 등급별 옵션'!$A$9:$D$13,2,FALSE),0)+IFERROR(VLOOKUP(G9,'장비 등급별 옵션'!$A$16:$D$20,2,FALSE),0)+IFERROR(VLOOKUP(H9,'장비 등급별 옵션'!$A$23:$D$27,2,FALSE),0)+IFERROR(VLOOKUP(I9,'장비 등급별 옵션'!$A$30:$D$34,2,FALSE),0)+IFERROR(VLOOKUP(J9,'장비 등급별 옵션'!$J$2:$N$6,2,FALSE),0)+IFERROR(VLOOKUP(K9,'장비 등급별 옵션'!$J$9:$N$13,2,FALSE),0)+IFERROR(VLOOKUP(L9,'장비 등급별 옵션'!$J$16:$N$20,2,FALSE),0)+IFERROR(VLOOKUP(M9,'장비 등급별 옵션'!$J$23:$N$27,2,FALSE),0)+IFERROR(VLOOKUP(N9,'장비 등급별 옵션'!$J$30:$N$34,2,FALSE),0)+IFERROR(VLOOKUP(O9,'장비 등급별 옵션'!$J$37:$N$40,2,FALSE),0) -> 35079 | U9: =IFERROR(VLOOKUP(E9,'장비 등급별 옵션'!$A$2:$D$6,4,FALSE),0)+IFERROR(VLOOKUP(F9,'장비 등급별 옵션'!$A$9:$D$13,4,FALSE),0)+IFERROR(VLOOKUP(G9,'장비 등급별 옵션'!$A$16:$D$20,4,FALSE),0)+IFERROR(VLOOKUP(H9,'장비 등급별 옵션'!$A$23:$D$27,4,FALSE),0)+IFERROR(VLOOKUP(I9,'장비 등급별 옵션'!$A$30:$D$34,4,FALSE),0)+IFERROR(VLOOKUP(J9,'장비 등급별 옵션'!$J$2:$N$6,4,FALSE),0)+IFERROR(VLOOKUP(K9,'장비 등급별 옵션'!$J$9:$N$13,4,FALSE),0)+IFERROR(VLOOKUP(L9,'장비 등급별 옵션'!$J$16:$N$20,4,FALSE),0)+IFERROR(VLOOKUP(M9,'장비 등급별 옵션'!$J$23:$N$27,4,FALSE),0)+IFERROR(VLOOKUP(N9,'장비 등급별 옵션'!$J$30:$N$34,4,FALSE),0)+IFERROR(VLOOKUP(O9,'장비 등급별 옵션'!$J$37:$N$40,4,FALSE),0) -> 130 | V9: =IFERROR(VLOOKUP(E9,'장비 등급별 옵션'!$A$2:$D$6,5,FALSE),0)+IFERROR(VLOOKUP(F9,'장비 등급별 옵션'!$A$9:$D$13,5,FALSE),0)+IFERROR(VLOOKUP(G9,'장비 등급별 옵션'!$A$16:$D$20,5,FALSE),0)+IFERROR(VLOOKUP(H9,'장비 등급별 옵션'!$A$23:$D$27,5,FALSE),0)+IFERROR(VLOOKUP(I9,'장비 등급별 옵션'!$A$30:$D$34,5,FALSE),0)+IFERROR(VLOOKUP(J9,'장비 등급별 옵션'!$J$2:$N$6,5,FALSE),0)+IFERROR(VLOOKUP(K9,'장비 등급별 옵션'!$J$9:$N$13,5,FALSE),0)+IFERROR(VLOOKUP(L9,'장비 등급별 옵션'!$J$16:$N$20,5,FALSE),0)+IFERROR(VLOOKUP(M9,'장비 등급별 옵션'!$J$23:$N$27,5,FALSE),0)+IFERROR(VLOOKUP(N9,'장비 등급별 옵션'!$J$30:$N$34,5,FALSE),0)+IFERROR(VLOOKUP(O9,'장비 등급별 옵션'!$J$37:$N$40,5,FALSE),0) -> 15 | W9: =IFERROR(VLOOKUP(E9,'장비 등급별 옵션'!$A$2:$H$6,5,FALSE),0)+IFERROR(VLOOKUP(F9,'장비 등급별 옵션'!$A$9:$H$13,5,FALSE),0)+IFERROR(VLOOKUP(G9,'장비 등급별 옵션'!$A$16:$H$20,5,FALSE),0)+IFERROR(VLOOKUP(H9,'장비 등급별 옵션'!$A$23:$H$27,5,FALSE),0)+IFERROR(VLOOKUP(I9,'장비 등급별 옵션'!$A$30:$H$34,5,FALSE),0)+IFERROR(VLOOKUP(J9,'장비 등급별 옵션'!$J$2:$R$6,6,FALSE),0)+IFERROR(VLOOKUP(K9,'장비 등급별 옵션'!$J$9:$R$13,6,FALSE),0)+IFERROR(VLOOKUP(L9,'장비 등급별 옵션'!$J$16:$R$20,6,FALSE),0)+IFERROR(VLOOKUP(M9,'장비 등급별 옵션'!$J$23:$R$27,6,FALSE),0)+IFERROR(VLOOKUP(N9,'장비 등급별 옵션'!$J$30:$R$34,6,FALSE),0)+IFERROR(VLOOKUP(O9,'장비 등급별 옵션'!$J$37:$R$40,6,FALSE),0) -> 1594 | X9: =(S9*((1.05+U9*0.0045)/1.05))/($S$25*((1.05+$U$25*0.0045)/1.05)) -> 0.68675741 | Y9: =IF($C$27="","",(1+($C$27+T9-$T$25+P9-$P$25)/100)/(1+$C$27/100)) -> 0.85382844 | Z9: =IF(OR(D9="",$D$25="",$Q$25=""),"",(1+(D9+168350+297900+TRUNC(3.08*(D9-$Q$25)+2886))/250)/(1+($D$25+168350+297900+TRUNC(3.08*($D$25-$Q$25)+2886))/250)) -> 0.99896618 | AA9: =IF(OR(C9="",X9="",Y9="",Z9=""),"",C9/X9/Y9/Z9) -> 3583.3373 | AB9: =IF(OR(C9="",$C$25=""),"",C9/$C$25) -> 0.15369408 | AC9: =IF(OR(AB9="",X9="",Y9="",Z9=""),"",AB9/X9/Y9/Z9) -> 0.262381 | AD9: =IF(R9="","",ROUND(R9,1)) -> 80.2 | AE9: =IF(OR($C$25="",X9="",Y9="",Z9="",AC9=""),"",ROUND($C$25*X9*Y9*Z9*AC9,0)) -> 2099 | AF9: =IF(OR(AE9="",C9=""),"",AE9-C9) -> 0
A10: 유니크 IV | B10: 1455 | C10: 2382 | D10: =$D$25+W10-$W$25 -> 6329 | E10: 레전더리 | F10: 레전더리 | G10: 레전더리 | H10: 유니크 | I10: 레전더리 | J10: 유니크 | K10: 유니크 | L10: 유니크 | M10: 유니크 | N10: 유니크 | O10: 유니크 | P10: 1732 | Q10: =IF(OR(R10="",R9=""),"",((1+R10/100)/(1+R9/100)-1)*100) -> 11.512793 | R10: =IF(OR(AC10="",$AC$2="",$R$25=""),"",(AC10/$AC$2*(1+$R$25/100)-1)*100) -> 100.91904 | S10: =(1+IFERROR(VLOOKUP(E10,'장비 등급별 옵션'!$A$2:$D$6,3,FALSE),0)/100)*(1+IFERROR(VLOOKUP(F10,'장비 등급별 옵션'!$A$9:$D$13,3,FALSE),0)/100)*(1+IFERROR(VLOOKUP(G10,'장비 등급별 옵션'!$A$16:$D$20,3,FALSE),0)/100)*(1+IFERROR(VLOOKUP(H10,'장비 등급별 옵션'!$A$23:$D$27,3,FALSE),0)/100)*(1+IFERROR(VLOOKUP(I10,'장비 등급별 옵션'!$A$30:$D$34,3,FALSE),0)/100)*(1+IFERROR(VLOOKUP(J10,'장비 등급별 옵션'!$J$2:$N$6,3,FALSE),0)/100)*(1+IFERROR(VLOOKUP(K10,'장비 등급별 옵션'!$J$9:$N$13,3,FALSE),0)/100)*(1+IFERROR(VLOOKUP(L10,'장비 등급별 옵션'!$J$16:$N$20,3,FALSE),0)/100)*(1+IFERROR(VLOOKUP(M10,'장비 등급별 옵션'!$J$23:$N$27,3,FALSE),0)/100)*(1+IFERROR(VLOOKUP(N10,'장비 등급별 옵션'!$J$30:$N$34,3,FALSE),0)/100)*(1+IFERROR(VLOOKUP(O10,'장비 등급별 옵션'!$J$37:$N$40,3,FALSE),0)/100) -> 92.663469 | T10: =IFERROR(VLOOKUP(E10,'장비 등급별 옵션'!$A$2:$D$6,2,FALSE),0)+IFERROR(VLOOKUP(F10,'장비 등급별 옵션'!$A$9:$D$13,2,FALSE),0)+IFERROR(VLOOKUP(G10,'장비 등급별 옵션'!$A$16:$D$20,2,FALSE),0)+IFERROR(VLOOKUP(H10,'장비 등급별 옵션'!$A$23:$D$27,2,FALSE),0)+IFERROR(VLOOKUP(I10,'장비 등급별 옵션'!$A$30:$D$34,2,FALSE),0)+IFERROR(VLOOKUP(J10,'장비 등급별 옵션'!$J$2:$N$6,2,FALSE),0)+IFERROR(VLOOKUP(K10,'장비 등급별 옵션'!$J$9:$N$13,2,FALSE),0)+IFERROR(VLOOKUP(L10,'장비 등급별 옵션'!$J$16:$N$20,2,FALSE),0)+IFERROR(VLOOKUP(M10,'장비 등급별 옵션'!$J$23:$N$27,2,FALSE),0)+IFERROR(VLOOKUP(N10,'장비 등급별 옵션'!$J$30:$N$34,2,FALSE),0)+IFERROR(VLOOKUP(O10,'장비 등급별 옵션'!$J$37:$N$40,2,FALSE),0) -> 35079 | U10: =IFERROR(VLOOKUP(E10,'장비 등급별 옵션'!$A$2:$D$6,4,FALSE),0)+IFERROR(VLOOKUP(F10,'장비 등급별 옵션'!$A$9:$D$13,4,FALSE),0)+IFERROR(VLOOKUP(G10,'장비 등급별 옵션'!$A$16:$D$20,4,FALSE),0)+IFERROR(VLOOKUP(H10,'장비 등급별 옵션'!$A$23:$D$27,4,FALSE),0)+IFERROR(VLOOKUP(I10,'장비 등급별 옵션'!$A$30:$D$34,4,FALSE),0)+IFERROR(VLOOKUP(J10,'장비 등급별 옵션'!$J$2:$N$6,4,FALSE),0)+IFERROR(VLOOKUP(K10,'장비 등급별 옵션'!$J$9:$N$13,4,FALSE),0)+IFERROR(VLOOKUP(L10,'장비 등급별 옵션'!$J$16:$N$20,4,FALSE),0)+IFERROR(VLOOKUP(M10,'장비 등급별 옵션'!$J$23:$N$27,4,FALSE),0)+IFERROR(VLOOKUP(N10,'장비 등급별 옵션'!$J$30:$N$34,4,FALSE),0)+IFERROR(VLOOKUP(O10,'장비 등급별 옵션'!$J$37:$N$40,4,FALSE),0) -> 130 | V10: =IFERROR(VLOOKUP(E10,'장비 등급별 옵션'!$A$2:$D$6,5,FALSE),0)+IFERROR(VLOOKUP(F10,'장비 등급별 옵션'!$A$9:$D$13,5,FALSE),0)+IFERROR(VLOOKUP(G10,'장비 등급별 옵션'!$A$16:$D$20,5,FALSE),0)+IFERROR(VLOOKUP(H10,'장비 등급별 옵션'!$A$23:$D$27,5,FALSE),0)+IFERROR(VLOOKUP(I10,'장비 등급별 옵션'!$A$30:$D$34,5,FALSE),0)+IFERROR(VLOOKUP(J10,'장비 등급별 옵션'!$J$2:$N$6,5,FALSE),0)+IFERROR(VLOOKUP(K10,'장비 등급별 옵션'!$J$9:$N$13,5,FALSE),0)+IFERROR(VLOOKUP(L10,'장비 등급별 옵션'!$J$16:$N$20,5,FALSE),0)+IFERROR(VLOOKUP(M10,'장비 등급별 옵션'!$J$23:$N$27,5,FALSE),0)+IFERROR(VLOOKUP(N10,'장비 등급별 옵션'!$J$30:$N$34,5,FALSE),0)+IFERROR(VLOOKUP(O10,'장비 등급별 옵션'!$J$37:$N$40,5,FALSE),0) -> 15 | W10: =IFERROR(VLOOKUP(E10,'장비 등급별 옵션'!$A$2:$H$6,5,FALSE),0)+IFERROR(VLOOKUP(F10,'장비 등급별 옵션'!$A$9:$H$13,5,FALSE),0)+IFERROR(VLOOKUP(G10,'장비 등급별 옵션'!$A$16:$H$20,5,FALSE),0)+IFERROR(VLOOKUP(H10,'장비 등급별 옵션'!$A$23:$H$27,5,FALSE),0)+IFERROR(VLOOKUP(I10,'장비 등급별 옵션'!$A$30:$H$34,5,FALSE),0)+IFERROR(VLOOKUP(J10,'장비 등급별 옵션'!$J$2:$R$6,6,FALSE),0)+IFERROR(VLOOKUP(K10,'장비 등급별 옵션'!$J$9:$R$13,6,FALSE),0)+IFERROR(VLOOKUP(L10,'장비 등급별 옵션'!$J$16:$R$20,6,FALSE),0)+IFERROR(VLOOKUP(M10,'장비 등급별 옵션'!$J$23:$R$27,6,FALSE),0)+IFERROR(VLOOKUP(N10,'장비 등급별 옵션'!$J$30:$R$34,6,FALSE),0)+IFERROR(VLOOKUP(O10,'장비 등급별 옵션'!$J$37:$R$40,6,FALSE),0) -> 1595 | X10: =(S10*((1.05+U10*0.0045)/1.05))/($S$25*((1.05+$U$25*0.0045)/1.05)) -> 0.69393919 | Y10: =IF($C$27="","",(1+($C$27+T10-$T$25+P10-$P$25)/100)/(1+$C$27/100)) -> 0.85990956 | Z10: =IF(OR(D10="",$D$25="",$Q$25=""),"",(1+(D10+168350+297900+TRUNC(3.08*(D10-$Q$25)+2886))/250)/(1+($D$25+168350+297900+TRUNC(3.08*($D$25-$Q$25)+2886))/250)) -> 0.99897631 | AA10: =IF(OR(C10="",X10="",Y10="",Z10=""),"",C10/X10/Y10/Z10) -> 3995.8795 | AB10: =IF(OR(C10="",$C$25=""),"",C10/$C$25) -> 0.17441605 | AC10: =IF(OR(AB10="",X10="",Y10="",Z10=""),"",AB10/X10/Y10/Z10) -> 0.29258838 | AD10: =IF(R10="","",ROUND(R10,1)) -> 100.9 | AE10: =IF(OR($C$25="",X10="",Y10="",Z10="",AC10=""),"",ROUND($C$25*X10*Y10*Z10*AC10,0)) -> 2382 | AF10: =IF(OR(AE10="",C10=""),"",AE10-C10) -> 0
A11: 유니크 V | B11: 1540 | C11: 2750 | D11: =$D$25+W11-$W$25 -> 6330 | E11: 레전더리 | F11: 레전더리 | G11: 레전더리 | H11: 레전더리 | I11: 레전더리 | J11: 레전더리 | K11: 유니크 | L11: 유니크 | M11: 유니크 | N11: 유니크 | O11: 유니크 | P11: 2598 | Q11: =IF(OR(R11="",R10=""),"",((1+R11/100)/(1+R10/100)-1)*100) -> 11.493442 | R11: =IF(OR(AC11="",$AC$2="",$R$25=""),"",(AC11/$AC$2*(1+$R$25/100)-1)*100) -> 124.01155 | S11: =(1+IFERROR(VLOOKUP(E11,'장비 등급별 옵션'!$A$2:$D$6,3,FALSE),0)/100)*(1+IFERROR(VLOOKUP(F11,'장비 등급별 옵션'!$A$9:$D$13,3,FALSE),0)/100)*(1+IFERROR(VLOOKUP(G11,'장비 등급별 옵션'!$A$16:$D$20,3,FALSE),0)/100)*(1+IFERROR(VLOOKUP(H11,'장비 등급별 옵션'!$A$23:$D$27,3,FALSE),0)/100)*(1+IFERROR(VLOOKUP(I11,'장비 등급별 옵션'!$A$30:$D$34,3,FALSE),0)/100)*(1+IFERROR(VLOOKUP(J11,'장비 등급별 옵션'!$J$2:$N$6,3,FALSE),0)/100)*(1+IFERROR(VLOOKUP(K11,'장비 등급별 옵션'!$J$9:$N$13,3,FALSE),0)/100)*(1+IFERROR(VLOOKUP(L11,'장비 등급별 옵션'!$J$16:$N$20,3,FALSE),0)/100)*(1+IFERROR(VLOOKUP(M11,'장비 등급별 옵션'!$J$23:$N$27,3,FALSE),0)/100)*(1+IFERROR(VLOOKUP(N11,'장비 등급별 옵션'!$J$30:$N$34,3,FALSE),0)/100)*(1+IFERROR(VLOOKUP(O11,'장비 등급별 옵션'!$J$37:$N$40,3,FALSE),0)/100) -> 94.612208 | T11: =IFERROR(VLOOKUP(E11,'장비 등급별 옵션'!$A$2:$D$6,2,FALSE),0)+IFERROR(VLOOKUP(F11,'장비 등급별 옵션'!$A$9:$D$13,2,FALSE),0)+IFERROR(VLOOKUP(G11,'장비 등급별 옵션'!$A$16:$D$20,2,FALSE),0)+IFERROR(VLOOKUP(H11,'장비 등급별 옵션'!$A$23:$D$27,2,FALSE),0)+IFERROR(VLOOKUP(I11,'장비 등급별 옵션'!$A$30:$D$34,2,FALSE),0)+IFERROR(VLOOKUP(J11,'장비 등급별 옵션'!$J$2:$N$6,2,FALSE),0)+IFERROR(VLOOKUP(K11,'장비 등급별 옵션'!$J$9:$N$13,2,FALSE),0)+IFERROR(VLOOKUP(L11,'장비 등급별 옵션'!$J$16:$N$20,2,FALSE),0)+IFERROR(VLOOKUP(M11,'장비 등급별 옵션'!$J$23:$N$27,2,FALSE),0)+IFERROR(VLOOKUP(N11,'장비 등급별 옵션'!$J$30:$N$34,2,FALSE),0)+IFERROR(VLOOKUP(O11,'장비 등급별 옵션'!$J$37:$N$40,2,FALSE),0) -> 35079 | U11: =IFERROR(VLOOKUP(E11,'장비 등급별 옵션'!$A$2:$D$6,4,FALSE),0)+IFERROR(VLOOKUP(F11,'장비 등급별 옵션'!$A$9:$D$13,4,FALSE),0)+IFERROR(VLOOKUP(G11,'장비 등급별 옵션'!$A$16:$D$20,4,FALSE),0)+IFERROR(VLOOKUP(H11,'장비 등급별 옵션'!$A$23:$D$27,4,FALSE),0)+IFERROR(VLOOKUP(I11,'장비 등급별 옵션'!$A$30:$D$34,4,FALSE),0)+IFERROR(VLOOKUP(J11,'장비 등급별 옵션'!$J$2:$N$6,4,FALSE),0)+IFERROR(VLOOKUP(K11,'장비 등급별 옵션'!$J$9:$N$13,4,FALSE),0)+IFERROR(VLOOKUP(L11,'장비 등급별 옵션'!$J$16:$N$20,4,FALSE),0)+IFERROR(VLOOKUP(M11,'장비 등급별 옵션'!$J$23:$N$27,4,FALSE),0)+IFERROR(VLOOKUP(N11,'장비 등급별 옵션'!$J$30:$N$34,4,FALSE),0)+IFERROR(VLOOKUP(O11,'장비 등급별 옵션'!$J$37:$N$40,4,FALSE),0) -> 130 | V11: =IFERROR(VLOOKUP(E11,'장비 등급별 옵션'!$A$2:$D$6,5,FALSE),0)+IFERROR(VLOOKUP(F11,'장비 등급별 옵션'!$A$9:$D$13,5,FALSE),0)+IFERROR(VLOOKUP(G11,'장비 등급별 옵션'!$A$16:$D$20,5,FALSE),0)+IFERROR(VLOOKUP(H11,'장비 등급별 옵션'!$A$23:$D$27,5,FALSE),0)+IFERROR(VLOOKUP(I11,'장비 등급별 옵션'!$A$30:$D$34,5,FALSE),0)+IFERROR(VLOOKUP(J11,'장비 등급별 옵션'!$J$2:$N$6,5,FALSE),0)+IFERROR(VLOOKUP(K11,'장비 등급별 옵션'!$J$9:$N$13,5,FALSE),0)+IFERROR(VLOOKUP(L11,'장비 등급별 옵션'!$J$16:$N$20,5,FALSE),0)+IFERROR(VLOOKUP(M11,'장비 등급별 옵션'!$J$23:$N$27,5,FALSE),0)+IFERROR(VLOOKUP(N11,'장비 등급별 옵션'!$J$30:$N$34,5,FALSE),0)+IFERROR(VLOOKUP(O11,'장비 등급별 옵션'!$J$37:$N$40,5,FALSE),0) -> 15 | W11: =IFERROR(VLOOKUP(E11,'장비 등급별 옵션'!$A$2:$H$6,5,FALSE),0)+IFERROR(VLOOKUP(F11,'장비 등급별 옵션'!$A$9:$H$13,5,FALSE),0)+IFERROR(VLOOKUP(G11,'장비 등급별 옵션'!$A$16:$H$20,5,FALSE),0)+IFERROR(VLOOKUP(H11,'장비 등급별 옵션'!$A$23:$H$27,5,FALSE),0)+IFERROR(VLOOKUP(I11,'장비 등급별 옵션'!$A$30:$H$34,5,FALSE),0)+IFERROR(VLOOKUP(J11,'장비 등급별 옵션'!$J$2:$R$6,6,FALSE),0)+IFERROR(VLOOKUP(K11,'장비 등급별 옵션'!$J$9:$R$13,6,FALSE),0)+IFERROR(VLOOKUP(L11,'장비 등급별 옵션'!$J$16:$R$20,6,FALSE),0)+IFERROR(VLOOKUP(M11,'장비 등급별 옵션'!$J$23:$R$27,6,FALSE),0)+IFERROR(VLOOKUP(N11,'장비 등급별 옵션'!$J$30:$R$34,6,FALSE),0)+IFERROR(VLOOKUP(O11,'장비 등급별 옵션'!$J$37:$R$40,6,FALSE),0) -> 1596 | X11: =(S11*((1.05+U11*0.0045)/1.05))/($S$25*((1.05+$U$25*0.0045)/1.05)) -> 0.70853293 | Y11: =IF($C$27="","",(1+($C$27+T11-$T$25+P11-$P$25)/100)/(1+$C$27/100)) -> 0.87207179 | Z11: =IF(OR(D11="",$D$25="",$Q$25=""),"",(1+(D11+168350+297900+TRUNC(3.08*(D11-$Q$25)+2886))/250)/(1+($D$25+168350+297900+TRUNC(3.08*($D$25-$Q$25)+2886))/250)) -> 0.99898442 | AA11: =IF(OR(C11="",X11="",Y11="",Z11=""),"",C11/X11/Y11/Z11) -> 4455.1435 | AB11: =IF(OR(C11="",$C$25=""),"",C11/$C$25) -> 0.20136194 | AC11: =IF(OR(AB11="",X11="",Y11="",Z11=""),"",AB11/X11/Y11/Z11) -> 0.32621685 | AD11: =IF(R11="","",ROUND(R11,1)) -> 124 | AE11: =IF(OR($C$25="",X11="",Y11="",Z11="",AC11=""),"",ROUND($C$25*X11*Y11*Z11*AC11,0)) -> 2750 | AF11: =IF(OR(AE11="",C11=""),"",AE11-C11) -> 0
A12: 레전더리 I | B12: 1650 | C12: 3631 | D12: =$D$25+W12-$W$25 -> 6333 | E12: 레전더리 | F12: 레전더리 | G12: 레전더리 | H12: 레전더리 | I12: 레전더리 | J12: 레전더리 | K12: 레전더리 | L12: 레전더리 | M12: 유니크 | N12: 유니크 | O12: 유니크 | P12: 3464 | Q12: =IF(OR(R12="",R11=""),"",((1+R12/100)/(1+R11/100)-1)*100) -> 27.529839 | R12: =IF(OR(AC12="",$AC$2="",$R$25=""),"",(AC12/$AC$2*(1+$R$25/100)-1)*100) -> 185.68157 | S12: =(1+IFERROR(VLOOKUP(E12,'장비 등급별 옵션'!$A$2:$D$6,3,FALSE),0)/100)*(1+IFERROR(VLOOKUP(F12,'장비 등급별 옵션'!$A$9:$D$13,3,FALSE),0)/100)*(1+IFERROR(VLOOKUP(G12,'장비 등급별 옵션'!$A$16:$D$20,3,FALSE),0)/100)*(1+IFERROR(VLOOKUP(H12,'장비 등급별 옵션'!$A$23:$D$27,3,FALSE),0)/100)*(1+IFERROR(VLOOKUP(I12,'장비 등급별 옵션'!$A$30:$D$34,3,FALSE),0)/100)*(1+IFERROR(VLOOKUP(J12,'장비 등급별 옵션'!$J$2:$N$6,3,FALSE),0)/100)*(1+IFERROR(VLOOKUP(K12,'장비 등급별 옵션'!$J$9:$N$13,3,FALSE),0)/100)*(1+IFERROR(VLOOKUP(L12,'장비 등급별 옵션'!$J$16:$N$20,3,FALSE),0)/100)*(1+IFERROR(VLOOKUP(M12,'장비 등급별 옵션'!$J$23:$N$27,3,FALSE),0)/100)*(1+IFERROR(VLOOKUP(N12,'장비 등급별 옵션'!$J$30:$N$34,3,FALSE),0)/100)*(1+IFERROR(VLOOKUP(O12,'장비 등급별 옵션'!$J$37:$N$40,3,FALSE),0)/100) -> 96.605835 | T12: =IFERROR(VLOOKUP(E12,'장비 등급별 옵션'!$A$2:$D$6,2,FALSE),0)+IFERROR(VLOOKUP(F12,'장비 등급별 옵션'!$A$9:$D$13,2,FALSE),0)+IFERROR(VLOOKUP(G12,'장비 등급별 옵션'!$A$16:$D$20,2,FALSE),0)+IFERROR(VLOOKUP(H12,'장비 등급별 옵션'!$A$23:$D$27,2,FALSE),0)+IFERROR(VLOOKUP(I12,'장비 등급별 옵션'!$A$30:$D$34,2,FALSE),0)+IFERROR(VLOOKUP(J12,'장비 등급별 옵션'!$J$2:$N$6,2,FALSE),0)+IFERROR(VLOOKUP(K12,'장비 등급별 옵션'!$J$9:$N$13,2,FALSE),0)+IFERROR(VLOOKUP(L12,'장비 등급별 옵션'!$J$16:$N$20,2,FALSE),0)+IFERROR(VLOOKUP(M12,'장비 등급별 옵션'!$J$23:$N$27,2,FALSE),0)+IFERROR(VLOOKUP(N12,'장비 등급별 옵션'!$J$30:$N$34,2,FALSE),0)+IFERROR(VLOOKUP(O12,'장비 등급별 옵션'!$J$37:$N$40,2,FALSE),0) -> 35079 | U12: =IFERROR(VLOOKUP(E12,'장비 등급별 옵션'!$A$2:$D$6,4,FALSE),0)+IFERROR(VLOOKUP(F12,'장비 등급별 옵션'!$A$9:$D$13,4,FALSE),0)+IFERROR(VLOOKUP(G12,'장비 등급별 옵션'!$A$16:$D$20,4,FALSE),0)+IFERROR(VLOOKUP(H12,'장비 등급별 옵션'!$A$23:$D$27,4,FALSE),0)+IFERROR(VLOOKUP(I12,'장비 등급별 옵션'!$A$30:$D$34,4,FALSE),0)+IFERROR(VLOOKUP(J12,'장비 등급별 옵션'!$J$2:$N$6,4,FALSE),0)+IFERROR(VLOOKUP(K12,'장비 등급별 옵션'!$J$9:$N$13,4,FALSE),0)+IFERROR(VLOOKUP(L12,'장비 등급별 옵션'!$J$16:$N$20,4,FALSE),0)+IFERROR(VLOOKUP(M12,'장비 등급별 옵션'!$J$23:$N$27,4,FALSE),0)+IFERROR(VLOOKUP(N12,'장비 등급별 옵션'!$J$30:$N$34,4,FALSE),0)+IFERROR(VLOOKUP(O12,'장비 등급별 옵션'!$J$37:$N$40,4,FALSE),0) -> 130 | V12: =IFERROR(VLOOKUP(E12,'장비 등급별 옵션'!$A$2:$D$6,5,FALSE),0)+IFERROR(VLOOKUP(F12,'장비 등급별 옵션'!$A$9:$D$13,5,FALSE),0)+IFERROR(VLOOKUP(G12,'장비 등급별 옵션'!$A$16:$D$20,5,FALSE),0)+IFERROR(VLOOKUP(H12,'장비 등급별 옵션'!$A$23:$D$27,5,FALSE),0)+IFERROR(VLOOKUP(I12,'장비 등급별 옵션'!$A$30:$D$34,5,FALSE),0)+IFERROR(VLOOKUP(J12,'장비 등급별 옵션'!$J$2:$N$6,5,FALSE),0)+IFERROR(VLOOKUP(K12,'장비 등급별 옵션'!$J$9:$N$13,5,FALSE),0)+IFERROR(VLOOKUP(L12,'장비 등급별 옵션'!$J$16:$N$20,5,FALSE),0)+IFERROR(VLOOKUP(M12,'장비 등급별 옵션'!$J$23:$N$27,5,FALSE),0)+IFERROR(VLOOKUP(N12,'장비 등급별 옵션'!$J$30:$N$34,5,FALSE),0)+IFERROR(VLOOKUP(O12,'장비 등급별 옵션'!$J$37:$N$40,5,FALSE),0) -> 15 | W12: =IFERROR(VLOOKUP(E12,'장비 등급별 옵션'!$A$2:$H$6,5,FALSE),0)+IFERROR(VLOOKUP(F12,'장비 등급별 옵션'!$A$9:$H$13,5,FALSE),0)+IFERROR(VLOOKUP(G12,'장비 등급별 옵션'!$A$16:$H$20,5,FALSE),0)+IFERROR(VLOOKUP(H12,'장비 등급별 옵션'!$A$23:$H$27,5,FALSE),0)+IFERROR(VLOOKUP(I12,'장비 등급별 옵션'!$A$30:$H$34,5,FALSE),0)+IFERROR(VLOOKUP(J12,'장비 등급별 옵션'!$J$2:$R$6,6,FALSE),0)+IFERROR(VLOOKUP(K12,'장비 등급별 옵션'!$J$9:$R$13,6,FALSE),0)+IFERROR(VLOOKUP(L12,'장비 등급별 옵션'!$J$16:$R$20,6,FALSE),0)+IFERROR(VLOOKUP(M12,'장비 등급별 옵션'!$J$23:$R$27,6,FALSE),0)+IFERROR(VLOOKUP(N12,'장비 등급별 옵션'!$J$30:$R$34,6,FALSE),0)+IFERROR(VLOOKUP(O12,'장비 등급별 옵션'!$J$37:$R$40,6,FALSE),0) -> 1599 | X12: =(S12*((1.05+U12*0.0045)/1.05))/($S$25*((1.05+$U$25*0.0045)/1.05)) -> 0.72346283 | Y12: =IF($C$27="","",(1+($C$27+T12-$T$25+P12-$P$25)/100)/(1+$C$27/100)) -> 0.88423403 | Z12: =IF(OR(D12="",$D$25="",$Q$25=""),"",(1+(D12+168350+297900+TRUNC(3.08*(D12-$Q$25)+2886))/250)/(1+($D$25+168350+297900+TRUNC(3.08*($D$25-$Q$25)+2886))/250)) -> 0.99900874 | AA12: =IF(OR(C12="",X12="",Y12="",Z12=""),"",C12/X12/Y12/Z12) -> 5681.6374 | AB12: =IF(OR(C12="",$C$25=""),"",C12/$C$25) -> 0.26587098 | AC12: =IF(OR(AB12="",X12="",Y12="",Z12=""),"",AB12/X12/Y12/Z12) -> 0.41602382 | AD12: =IF(R12="","",ROUND(R12,1)) -> 185.7 | AE12: =IF(OR($C$25="",X12="",Y12="",Z12="",AC12=""),"",ROUND($C$25*X12*Y12*Z12*AC12,0)) -> 3631 | AF12: =IF(OR(AE12="",C12=""),"",AE12-C12) -> 0
A13: 레전더리 II | B13: 1735 | C13: 4092 | D13: =$D$25+W13-$W$25 -> 6336 | E13: 레전더리 | F13: 레전더리 | G13: 레전더리 | H13: 레전더리 | I13: 레전더리 | J13: 레전더리 | K13: 레전더리 | L13: 레전더리 | M13: 레전더리 | N13: 레전더리 | O13: 유니크 | P13: 4330 | Q13: =IF(OR(R13="",R12=""),"",((1+R13/100)/(1+R12/100)-1)*100) -> 8.8595635 | R13: =IF(OR(AC13="",$AC$2="",$R$25=""),"",(AC13/$AC$2*(1+$R$25/100)-1)*100) -> 210.99171 | S13: =(1+IFERROR(VLOOKUP(E13,'장비 등급별 옵션'!$A$2:$D$6,3,FALSE),0)/100)*(1+IFERROR(VLOOKUP(F13,'장비 등급별 옵션'!$A$9:$D$13,3,FALSE),0)/100)*(1+IFERROR(VLOOKUP(G13,'장비 등급별 옵션'!$A$16:$D$20,3,FALSE),0)/100)*(1+IFERROR(VLOOKUP(H13,'장비 등급별 옵션'!$A$23:$D$27,3,FALSE),0)/100)*(1+IFERROR(VLOOKUP(I13,'장비 등급별 옵션'!$A$30:$D$34,3,FALSE),0)/100)*(1+IFERROR(VLOOKUP(J13,'장비 등급별 옵션'!$J$2:$N$6,3,FALSE),0)/100)*(1+IFERROR(VLOOKUP(K13,'장비 등급별 옵션'!$J$9:$N$13,3,FALSE),0)/100)*(1+IFERROR(VLOOKUP(L13,'장비 등급별 옵션'!$J$16:$N$20,3,FALSE),0)/100)*(1+IFERROR(VLOOKUP(M13,'장비 등급별 옵션'!$J$23:$N$27,3,FALSE),0)/100)*(1+IFERROR(VLOOKUP(N13,'장비 등급별 옵션'!$J$30:$N$34,3,FALSE),0)/100)*(1+IFERROR(VLOOKUP(O13,'장비 등급별 옵션'!$J$37:$N$40,3,FALSE),0)/100) -> 98.651288 | T13: =IFERROR(VLOOKUP(E13,'장비 등급별 옵션'!$A$2:$D$6,2,FALSE),0)+IFERROR(VLOOKUP(F13,'장비 등급별 옵션'!$A$9:$D$13,2,FALSE),0)+IFERROR(VLOOKUP(G13,'장비 등급별 옵션'!$A$16:$D$20,2,FALSE),0)+IFERROR(VLOOKUP(H13,'장비 등급별 옵션'!$A$23:$D$27,2,FALSE),0)+IFERROR(VLOOKUP(I13,'장비 등급별 옵션'!$A$30:$D$34,2,FALSE),0)+IFERROR(VLOOKUP(J13,'장비 등급별 옵션'!$J$2:$N$6,2,FALSE),0)+IFERROR(VLOOKUP(K13,'장비 등급별 옵션'!$J$9:$N$13,2,FALSE),0)+IFERROR(VLOOKUP(L13,'장비 등급별 옵션'!$J$16:$N$20,2,FALSE),0)+IFERROR(VLOOKUP(M13,'장비 등급별 옵션'!$J$23:$N$27,2,FALSE),0)+IFERROR(VLOOKUP(N13,'장비 등급별 옵션'!$J$30:$N$34,2,FALSE),0)+IFERROR(VLOOKUP(O13,'장비 등급별 옵션'!$J$37:$N$40,2,FALSE),0) -> 35079 | U13: =IFERROR(VLOOKUP(E13,'장비 등급별 옵션'!$A$2:$D$6,4,FALSE),0)+IFERROR(VLOOKUP(F13,'장비 등급별 옵션'!$A$9:$D$13,4,FALSE),0)+IFERROR(VLOOKUP(G13,'장비 등급별 옵션'!$A$16:$D$20,4,FALSE),0)+IFERROR(VLOOKUP(H13,'장비 등급별 옵션'!$A$23:$D$27,4,FALSE),0)+IFERROR(VLOOKUP(I13,'장비 등급별 옵션'!$A$30:$D$34,4,FALSE),0)+IFERROR(VLOOKUP(J13,'장비 등급별 옵션'!$J$2:$N$6,4,FALSE),0)+IFERROR(VLOOKUP(K13,'장비 등급별 옵션'!$J$9:$N$13,4,FALSE),0)+IFERROR(VLOOKUP(L13,'장비 등급별 옵션'!$J$16:$N$20,4,FALSE),0)+IFERROR(VLOOKUP(M13,'장비 등급별 옵션'!$J$23:$N$27,4,FALSE),0)+IFERROR(VLOOKUP(N13,'장비 등급별 옵션'!$J$30:$N$34,4,FALSE),0)+IFERROR(VLOOKUP(O13,'장비 등급별 옵션'!$J$37:$N$40,4,FALSE),0) -> 130 | V13: =IFERROR(VLOOKUP(E13,'장비 등급별 옵션'!$A$2:$D$6,5,FALSE),0)+IFERROR(VLOOKUP(F13,'장비 등급별 옵션'!$A$9:$D$13,5,FALSE),0)+IFERROR(VLOOKUP(G13,'장비 등급별 옵션'!$A$16:$D$20,5,FALSE),0)+IFERROR(VLOOKUP(H13,'장비 등급별 옵션'!$A$23:$D$27,5,FALSE),0)+IFERROR(VLOOKUP(I13,'장비 등급별 옵션'!$A$30:$D$34,5,FALSE),0)+IFERROR(VLOOKUP(J13,'장비 등급별 옵션'!$J$2:$N$6,5,FALSE),0)+IFERROR(VLOOKUP(K13,'장비 등급별 옵션'!$J$9:$N$13,5,FALSE),0)+IFERROR(VLOOKUP(L13,'장비 등급별 옵션'!$J$16:$N$20,5,FALSE),0)+IFERROR(VLOOKUP(M13,'장비 등급별 옵션'!$J$23:$N$27,5,FALSE),0)+IFERROR(VLOOKUP(N13,'장비 등급별 옵션'!$J$30:$N$34,5,FALSE),0)+IFERROR(VLOOKUP(O13,'장비 등급별 옵션'!$J$37:$N$40,5,FALSE),0) -> 15 | W13: =IFERROR(VLOOKUP(E13,'장비 등급별 옵션'!$A$2:$H$6,5,FALSE),0)+IFERROR(VLOOKUP(F13,'장비 등급별 옵션'!$A$9:$H$13,5,FALSE),0)+IFERROR(VLOOKUP(G13,'장비 등급별 옵션'!$A$16:$H$20,5,FALSE),0)+IFERROR(VLOOKUP(H13,'장비 등급별 옵션'!$A$23:$H$27,5,FALSE),0)+IFERROR(VLOOKUP(I13,'장비 등급별 옵션'!$A$30:$H$34,5,FALSE),0)+IFERROR(VLOOKUP(J13,'장비 등급별 옵션'!$J$2:$R$6,6,FALSE),0)+IFERROR(VLOOKUP(K13,'장비 등급별 옵션'!$J$9:$R$13,6,FALSE),0)+IFERROR(VLOOKUP(L13,'장비 등급별 옵션'!$J$16:$R$20,6,FALSE),0)+IFERROR(VLOOKUP(M13,'장비 등급별 옵션'!$J$23:$R$27,6,FALSE),0)+IFERROR(VLOOKUP(N13,'장비 등급별 옵션'!$J$30:$R$34,6,FALSE),0)+IFERROR(VLOOKUP(O13,'장비 등급별 옵션'!$J$37:$R$40,6,FALSE),0) -> 1602 | X13: =(S13*((1.05+U13*0.0045)/1.05))/($S$25*((1.05+$U$25*0.0045)/1.05)) -> 0.73878083 | Y13: =IF($C$27="","",(1+($C$27+T13-$T$25+P13-$P$25)/100)/(1+$C$27/100)) -> 0.89639627 | Z13: =IF(OR(D13="",$D$25="",$Q$25=""),"",(1+(D13+168350+297900+TRUNC(3.08*(D13-$Q$25)+2886))/250)/(1+($D$25+168350+297900+TRUNC(3.08*($D$25-$Q$25)+2886))/250)) -> 0.99903307 | AA13: =IF(OR(C13="",X13="",Y13="",Z13=""),"",C13/X13/Y13/Z13) -> 6185.0056 | AB13: =IF(OR(C13="",$C$25=""),"",C13/$C$25) -> 0.29962657 | AC13: =IF(OR(AB13="",X13="",Y13="",Z13=""),"",AB13/X13/Y13/Z13) -> 0.45288172 | AD13: =IF(R13="","",ROUND(R13,1)) -> 211 | AE13: =IF(OR($C$25="",X13="",Y13="",Z13="",AC13=""),"",ROUND($C$25*X13*Y13*Z13*AC13,0)) -> 4092 | AF13: =IF(OR(AE13="",C13=""),"",AE13-C13) -> 0
A14: 레전더리 III | B14: 1820 | C14: 4597 | D14: =$D$25+W14-$W$25 -> 6389 | E14: 에픽 | F14: 레전더리 | G14: 레전더리 | H14: 레전더리 | I14: 레전더리 | J14: 레전더리 | K14: 레전더리 | L14: 레전더리 | M14: 레전더리 | N14: 레전더리 | O14: 레전더리 | P14: 5247 | Q14: =IF(OR(R14="",R13=""),"",((1+R14/100)/(1+R13/100)-1)*100) -> 8.5030661 | R14: =IF(OR(AC14="",$AC$2="",$R$25=""),"",(AC14/$AC$2*(1+$R$25/100)-1)*100) -> 237.43554 | S14: =(1+IFERROR(VLOOKUP(E14,'장비 등급별 옵션'!$A$2:$D$6,3,FALSE),0)/100)*(1+IFERROR(VLOOKUP(F14,'장비 등급별 옵션'!$A$9:$D$13,3,FALSE),0)/100)*(1+IFERROR(VLOOKUP(G14,'장비 등급별 옵션'!$A$16:$D$20,3,FALSE),0)/100)*(1+IFERROR(VLOOKUP(H14,'장비 등급별 옵션'!$A$23:$D$27,3,FALSE),0)/100)*(1+IFERROR(VLOOKUP(I14,'장비 등급별 옵션'!$A$30:$D$34,3,FALSE),0)/100)*(1+IFERROR(VLOOKUP(J14,'장비 등급별 옵션'!$J$2:$N$6,3,FALSE),0)/100)*(1+IFERROR(VLOOKUP(K14,'장비 등급별 옵션'!$J$9:$N$13,3,FALSE),0)/100)*(1+IFERROR(VLOOKUP(L14,'장비 등급별 옵션'!$J$16:$N$20,3,FALSE),0)/100)*(1+IFERROR(VLOOKUP(M14,'장비 등급별 옵션'!$J$23:$N$27,3,FALSE),0)/100)*(1+IFERROR(VLOOKUP(N14,'장비 등급별 옵션'!$J$30:$N$34,3,FALSE),0)/100)*(1+IFERROR(VLOOKUP(O14,'장비 등급별 옵션'!$J$37:$N$40,3,FALSE),0)/100) -> 100.6501 | T14: =IFERROR(VLOOKUP(E14,'장비 등급별 옵션'!$A$2:$D$6,2,FALSE),0)+IFERROR(VLOOKUP(F14,'장비 등급별 옵션'!$A$9:$D$13,2,FALSE),0)+IFERROR(VLOOKUP(G14,'장비 등급별 옵션'!$A$16:$D$20,2,FALSE),0)+IFERROR(VLOOKUP(H14,'장비 등급별 옵션'!$A$23:$D$27,2,FALSE),0)+IFERROR(VLOOKUP(I14,'장비 등급별 옵션'!$A$30:$D$34,2,FALSE),0)+IFERROR(VLOOKUP(J14,'장비 등급별 옵션'!$J$2:$N$6,2,FALSE),0)+IFERROR(VLOOKUP(K14,'장비 등급별 옵션'!$J$9:$N$13,2,FALSE),0)+IFERROR(VLOOKUP(L14,'장비 등급별 옵션'!$J$16:$N$20,2,FALSE),0)+IFERROR(VLOOKUP(M14,'장비 등급별 옵션'!$J$23:$N$27,2,FALSE),0)+IFERROR(VLOOKUP(N14,'장비 등급별 옵션'!$J$30:$N$34,2,FALSE),0)+IFERROR(VLOOKUP(O14,'장비 등급별 옵션'!$J$37:$N$40,2,FALSE),0) -> 35079 | U14: =IFERROR(VLOOKUP(E14,'장비 등급별 옵션'!$A$2:$D$6,4,FALSE),0)+IFERROR(VLOOKUP(F14,'장비 등급별 옵션'!$A$9:$D$13,4,FALSE),0)+IFERROR(VLOOKUP(G14,'장비 등급별 옵션'!$A$16:$D$20,4,FALSE),0)+IFERROR(VLOOKUP(H14,'장비 등급별 옵션'!$A$23:$D$27,4,FALSE),0)+IFERROR(VLOOKUP(I14,'장비 등급별 옵션'!$A$30:$D$34,4,FALSE),0)+IFERROR(VLOOKUP(J14,'장비 등급별 옵션'!$J$2:$N$6,4,FALSE),0)+IFERROR(VLOOKUP(K14,'장비 등급별 옵션'!$J$9:$N$13,4,FALSE),0)+IFERROR(VLOOKUP(L14,'장비 등급별 옵션'!$J$16:$N$20,4,FALSE),0)+IFERROR(VLOOKUP(M14,'장비 등급별 옵션'!$J$23:$N$27,4,FALSE),0)+IFERROR(VLOOKUP(N14,'장비 등급별 옵션'!$J$30:$N$34,4,FALSE),0)+IFERROR(VLOOKUP(O14,'장비 등급별 옵션'!$J$37:$N$40,4,FALSE),0) -> 130 | V14: =IFERROR(VLOOKUP(E14,'장비 등급별 옵션'!$A$2:$D$6,5,FALSE),0)+IFERROR(VLOOKUP(F14,'장비 등급별 옵션'!$A$9:$D$13,5,FALSE),0)+IFERROR(VLOOKUP(G14,'장비 등급별 옵션'!$A$16:$D$20,5,FALSE),0)+IFERROR(VLOOKUP(H14,'장비 등급별 옵션'!$A$23:$D$27,5,FALSE),0)+IFERROR(VLOOKUP(I14,'장비 등급별 옵션'!$A$30:$D$34,5,FALSE),0)+IFERROR(VLOOKUP(J14,'장비 등급별 옵션'!$J$2:$N$6,5,FALSE),0)+IFERROR(VLOOKUP(K14,'장비 등급별 옵션'!$J$9:$N$13,5,FALSE),0)+IFERROR(VLOOKUP(L14,'장비 등급별 옵션'!$J$16:$N$20,5,FALSE),0)+IFERROR(VLOOKUP(M14,'장비 등급별 옵션'!$J$23:$N$27,5,FALSE),0)+IFERROR(VLOOKUP(N14,'장비 등급별 옵션'!$J$30:$N$34,5,FALSE),0)+IFERROR(VLOOKUP(O14,'장비 등급별 옵션'!$J$37:$N$40,5,FALSE),0) -> 15 | W14: =IFERROR(VLOOKUP(E14,'장비 등급별 옵션'!$A$2:$H$6,5,FALSE),0)+IFERROR(VLOOKUP(F14,'장비 등급별 옵션'!$A$9:$H$13,5,FALSE),0)+IFERROR(VLOOKUP(G14,'장비 등급별 옵션'!$A$16:$H$20,5,FALSE),0)+IFERROR(VLOOKUP(H14,'장비 등급별 옵션'!$A$23:$H$27,5,FALSE),0)+IFERROR(VLOOKUP(I14,'장비 등급별 옵션'!$A$30:$H$34,5,FALSE),0)+IFERROR(VLOOKUP(J14,'장비 등급별 옵션'!$J$2:$R$6,6,FALSE),0)+IFERROR(VLOOKUP(K14,'장비 등급별 옵션'!$J$9:$R$13,6,FALSE),0)+IFERROR(VLOOKUP(L14,'장비 등급별 옵션'!$J$16:$R$20,6,FALSE),0)+IFERROR(VLOOKUP(M14,'장비 등급별 옵션'!$J$23:$R$27,6,FALSE),0)+IFERROR(VLOOKUP(N14,'장비 등급별 옵션'!$J$30:$R$34,6,FALSE),0)+IFERROR(VLOOKUP(O14,'장비 등급별 옵션'!$J$37:$R$40,6,FALSE),0) -> 1655 | X14: =(S14*((1.05+U14*0.0045)/1.05))/($S$25*((1.05+$U$25*0.0045)/1.05)) -> 0.7537496 | Y14: =IF($C$27="","",(1+($C$27+T14-$T$25+P14-$P$25)/100)/(1+$C$27/100)) -> 0.90927476 | Z14: =IF(OR(D14="",$D$25="",$Q$25=""),"",(1+(D14+168350+297900+TRUNC(3.08*(D14-$Q$25)+2886))/250)/(1+($D$25+168350+297900+TRUNC(3.08*($D$25-$Q$25)+2886))/250)) -> 0.99947093 | AA14: =IF(OR(C14="",X14="",Y14="",Z14=""),"",C14/X14/Y14/Z14) -> 6710.9208 | AB14: =IF(OR(C14="",$C$25=""),"",C14/$C$25) -> 0.33660394 | AC14: =IF(OR(AB14="",X14="",Y14="",Z14=""),"",AB14/X14/Y14/Z14) -> 0.49139055 | AD14: =IF(R14="","",ROUND(R14,1)) -> 237.4 | AE14: =IF(OR($C$25="",X14="",Y14="",Z14="",AC14=""),"",ROUND($C$25*X14*Y14*Z14*AC14,0)) -> 4597 | AF14: =IF(OR(AE14="",C14=""),"",AE14-C14) -> 0
